2023-03-21 14:45:59,662 ERROR Heartbeat failed, response is {
    "error": "error",
    "data": "Invalid token"
}
Traceback (most recent call last):
  File "/code/service.py", line 26, in _request
    raise JudgeServiceError(r["data"])
exception.JudgeServiceError
2023-03-21 14:45:59,663 ERROR 
Traceback (most recent call last):
  File "/code/service.py", line 26, in _request
    raise JudgeServiceError(r["data"])
exception.JudgeServiceError

During handling of the above exception, another exception occurred:

Traceback (most recent call last):
  File "/code/service.py", line 42, in <module>
    service.heartbeat()
  File "/code/service.py", line 35, in heartbeat
    self._request(data)
  File "/code/service.py", line 29, in _request
    raise JudgeServiceError("Invalid heartbeat response")
exception.JudgeServiceError
2023-03-21 14:46:04,925 ERROR Heartbeat failed, response is {
    "error": "error",
    "data": "Invalid token"
}
Traceback (most recent call last):
  File "/code/service.py", line 26, in _request
    raise JudgeServiceError(r["data"])
exception.JudgeServiceError
2023-03-21 14:46:04,925 ERROR 
Traceback (most recent call last):
  File "/code/service.py", line 26, in _request
    raise JudgeServiceError(r["data"])
exception.JudgeServiceError

During handling of the above exception, another exception occurred:

Traceback (most recent call last):
  File "/code/service.py", line 42, in <module>
    service.heartbeat()
  File "/code/service.py", line 35, in heartbeat
    self._request(data)
  File "/code/service.py", line 29, in _request
    raise JudgeServiceError("Invalid heartbeat response")
exception.JudgeServiceError
2023-03-21 14:46:10,117 ERROR Heartbeat failed, response is {
    "error": "error",
    "data": "Invalid token"
}
Traceback (most recent call last):
  File "/code/service.py", line 26, in _request
    raise JudgeServiceError(r["data"])
exception.JudgeServiceError
2023-03-21 14:46:10,117 ERROR 
Traceback (most recent call last):
  File "/code/service.py", line 26, in _request
    raise JudgeServiceError(r["data"])
exception.JudgeServiceError

During handling of the above exception, another exception occurred:

Traceback (most recent call last):
  File "/code/service.py", line 42, in <module>
    service.heartbeat()
  File "/code/service.py", line 35, in heartbeat
    self._request(data)
  File "/code/service.py", line 29, in _request
    raise JudgeServiceError("Invalid heartbeat response")
exception.JudgeServiceError
2023-03-21 14:46:15,376 ERROR Heartbeat failed, response is {
    "error": "error",
    "data": "Invalid token"
}
Traceback (most recent call last):
  File "/code/service.py", line 26, in _request
    raise JudgeServiceError(r["data"])
exception.JudgeServiceError
2023-03-21 14:46:15,376 ERROR 
Traceback (most recent call last):
  File "/code/service.py", line 26, in _request
    raise JudgeServiceError(r["data"])
exception.JudgeServiceError

During handling of the above exception, another exception occurred:

Traceback (most recent call last):
  File "/code/service.py", line 42, in <module>
    service.heartbeat()
  File "/code/service.py", line 35, in heartbeat
    self._request(data)
  File "/code/service.py", line 29, in _request
    raise JudgeServiceError("Invalid heartbeat response")
exception.JudgeServiceError
2023-03-21 14:46:20,568 ERROR Heartbeat failed, response is {
    "error": "error",
    "data": "Invalid token"
}
Traceback (most recent call last):
  File "/code/service.py", line 26, in _request
    raise JudgeServiceError(r["data"])
exception.JudgeServiceError
2023-03-21 14:46:20,568 ERROR 
Traceback (most recent call last):
  File "/code/service.py", line 26, in _request
    raise JudgeServiceError(r["data"])
exception.JudgeServiceError

During handling of the above exception, another exception occurred:

Traceback (most recent call last):
  File "/code/service.py", line 42, in <module>
    service.heartbeat()
  File "/code/service.py", line 35, in heartbeat
    self._request(data)
  File "/code/service.py", line 29, in _request
    raise JudgeServiceError("Invalid heartbeat response")
exception.JudgeServiceError
2023-03-21 14:46:25,758 ERROR Heartbeat failed, response is {
    "error": "error",
    "data": "Invalid token"
}
Traceback (most recent call last):
  File "/code/service.py", line 26, in _request
    raise JudgeServiceError(r["data"])
exception.JudgeServiceError
2023-03-21 14:46:25,758 ERROR 
Traceback (most recent call last):
  File "/code/service.py", line 26, in _request
    raise JudgeServiceError(r["data"])
exception.JudgeServiceError

During handling of the above exception, another exception occurred:

Traceback (most recent call last):
  File "/code/service.py", line 42, in <module>
    service.heartbeat()
  File "/code/service.py", line 35, in heartbeat
    self._request(data)
  File "/code/service.py", line 29, in _request
    raise JudgeServiceError("Invalid heartbeat response")
exception.JudgeServiceError
2023-03-21 14:46:30,949 ERROR Heartbeat failed, response is {
    "error": "error",
    "data": "Invalid token"
}
Traceback (most recent call last):
  File "/code/service.py", line 26, in _request
    raise JudgeServiceError(r["data"])
exception.JudgeServiceError
2023-03-21 14:46:30,949 ERROR 
Traceback (most recent call last):
  File "/code/service.py", line 26, in _request
    raise JudgeServiceError(r["data"])
exception.JudgeServiceError

During handling of the above exception, another exception occurred:

Traceback (most recent call last):
  File "/code/service.py", line 42, in <module>
    service.heartbeat()
  File "/code/service.py", line 35, in heartbeat
    self._request(data)
  File "/code/service.py", line 29, in _request
    raise JudgeServiceError("Invalid heartbeat response")
exception.JudgeServiceError
2023-03-21 14:46:36,203 ERROR Heartbeat failed, response is {
    "error": "error",
    "data": "Invalid token"
}
Traceback (most recent call last):
  File "/code/service.py", line 26, in _request
    raise JudgeServiceError(r["data"])
exception.JudgeServiceError
2023-03-21 14:46:36,203 ERROR 
Traceback (most recent call last):
  File "/code/service.py", line 26, in _request
    raise JudgeServiceError(r["data"])
exception.JudgeServiceError

During handling of the above exception, another exception occurred:

Traceback (most recent call last):
  File "/code/service.py", line 42, in <module>
    service.heartbeat()
  File "/code/service.py", line 35, in heartbeat
    self._request(data)
  File "/code/service.py", line 29, in _request
    raise JudgeServiceError("Invalid heartbeat response")
exception.JudgeServiceError
2023-03-21 14:46:41,413 ERROR Heartbeat failed, response is {
    "error": "error",
    "data": "Invalid token"
}
Traceback (most recent call last):
  File "/code/service.py", line 26, in _request
    raise JudgeServiceError(r["data"])
exception.JudgeServiceError
2023-03-21 14:46:41,414 ERROR 
Traceback (most recent call last):
  File "/code/service.py", line 26, in _request
    raise JudgeServiceError(r["data"])
exception.JudgeServiceError

During handling of the above exception, another exception occurred:

Traceback (most recent call last):
  File "/code/service.py", line 42, in <module>
    service.heartbeat()
  File "/code/service.py", line 35, in heartbeat
    self._request(data)
  File "/code/service.py", line 29, in _request
    raise JudgeServiceError("Invalid heartbeat response")
exception.JudgeServiceError
2023-03-21 14:46:46,723 ERROR Heartbeat failed, response is {
    "error": "error",
    "data": "Invalid token"
}
Traceback (most recent call last):
  File "/code/service.py", line 26, in _request
    raise JudgeServiceError(r["data"])
exception.JudgeServiceError
2023-03-21 14:46:46,723 ERROR 
Traceback (most recent call last):
  File "/code/service.py", line 26, in _request
    raise JudgeServiceError(r["data"])
exception.JudgeServiceError

During handling of the above exception, another exception occurred:

Traceback (most recent call last):
  File "/code/service.py", line 42, in <module>
    service.heartbeat()
  File "/code/service.py", line 35, in heartbeat
    self._request(data)
  File "/code/service.py", line 29, in _request
    raise JudgeServiceError("Invalid heartbeat response")
exception.JudgeServiceError
2023-03-21 14:46:52,014 ERROR Heartbeat failed, response is {
    "error": "error",
    "data": "Invalid token"
}
Traceback (most recent call last):
  File "/code/service.py", line 26, in _request
    raise JudgeServiceError(r["data"])
exception.JudgeServiceError
2023-03-21 14:46:52,015 ERROR 
Traceback (most recent call last):
  File "/code/service.py", line 26, in _request
    raise JudgeServiceError(r["data"])
exception.JudgeServiceError

During handling of the above exception, another exception occurred:

Traceback (most recent call last):
  File "/code/service.py", line 42, in <module>
    service.heartbeat()
  File "/code/service.py", line 35, in heartbeat
    self._request(data)
  File "/code/service.py", line 29, in _request
    raise JudgeServiceError("Invalid heartbeat response")
exception.JudgeServiceError
2023-03-21 14:46:57,223 ERROR Heartbeat failed, response is {
    "error": "error",
    "data": "Invalid token"
}
Traceback (most recent call last):
  File "/code/service.py", line 26, in _request
    raise JudgeServiceError(r["data"])
exception.JudgeServiceError
2023-03-21 14:46:57,223 ERROR 
Traceback (most recent call last):
  File "/code/service.py", line 26, in _request
    raise JudgeServiceError(r["data"])
exception.JudgeServiceError

During handling of the above exception, another exception occurred:

Traceback (most recent call last):
  File "/code/service.py", line 42, in <module>
    service.heartbeat()
  File "/code/service.py", line 35, in heartbeat
    self._request(data)
  File "/code/service.py", line 29, in _request
    raise JudgeServiceError("Invalid heartbeat response")
exception.JudgeServiceError
2023-03-21 14:47:02,525 ERROR Heartbeat failed, response is {
    "error": "error",
    "data": "Invalid token"
}
Traceback (most recent call last):
  File "/code/service.py", line 26, in _request
    raise JudgeServiceError(r["data"])
exception.JudgeServiceError
2023-03-21 14:47:02,525 ERROR 
Traceback (most recent call last):
  File "/code/service.py", line 26, in _request
    raise JudgeServiceError(r["data"])
exception.JudgeServiceError

During handling of the above exception, another exception occurred:

Traceback (most recent call last):
  File "/code/service.py", line 42, in <module>
    service.heartbeat()
  File "/code/service.py", line 35, in heartbeat
    self._request(data)
  File "/code/service.py", line 29, in _request
    raise JudgeServiceError("Invalid heartbeat response")
exception.JudgeServiceError
2023-03-21 14:47:07,804 ERROR Heartbeat failed, response is {
    "error": "error",
    "data": "Invalid token"
}
Traceback (most recent call last):
  File "/code/service.py", line 26, in _request
    raise JudgeServiceError(r["data"])
exception.JudgeServiceError
2023-03-21 14:47:07,804 ERROR 
Traceback (most recent call last):
  File "/code/service.py", line 26, in _request
    raise JudgeServiceError(r["data"])
exception.JudgeServiceError

During handling of the above exception, another exception occurred:

Traceback (most recent call last):
  File "/code/service.py", line 42, in <module>
    service.heartbeat()
  File "/code/service.py", line 35, in heartbeat
    self._request(data)
  File "/code/service.py", line 29, in _request
    raise JudgeServiceError("Invalid heartbeat response")
exception.JudgeServiceError
2023-03-21 14:47:13,013 ERROR Heartbeat failed, response is {
    "error": "error",
    "data": "Invalid token"
}
Traceback (most recent call last):
  File "/code/service.py", line 26, in _request
    raise JudgeServiceError(r["data"])
exception.JudgeServiceError
2023-03-21 14:47:13,013 ERROR 
Traceback (most recent call last):
  File "/code/service.py", line 26, in _request
    raise JudgeServiceError(r["data"])
exception.JudgeServiceError

During handling of the above exception, another exception occurred:

Traceback (most recent call last):
  File "/code/service.py", line 42, in <module>
    service.heartbeat()
  File "/code/service.py", line 35, in heartbeat
    self._request(data)
  File "/code/service.py", line 29, in _request
    raise JudgeServiceError("Invalid heartbeat response")
exception.JudgeServiceError
2023-03-21 14:47:18,210 ERROR Heartbeat failed, response is {
    "error": "error",
    "data": "Invalid token"
}
Traceback (most recent call last):
  File "/code/service.py", line 26, in _request
    raise JudgeServiceError(r["data"])
exception.JudgeServiceError
2023-03-21 14:47:18,210 ERROR 
Traceback (most recent call last):
  File "/code/service.py", line 26, in _request
    raise JudgeServiceError(r["data"])
exception.JudgeServiceError

During handling of the above exception, another exception occurred:

Traceback (most recent call last):
  File "/code/service.py", line 42, in <module>
    service.heartbeat()
  File "/code/service.py", line 35, in heartbeat
    self._request(data)
  File "/code/service.py", line 29, in _request
    raise JudgeServiceError("Invalid heartbeat response")
exception.JudgeServiceError
2023-03-21 14:47:23,409 ERROR Heartbeat failed, response is {
    "error": "error",
    "data": "Invalid token"
}
Traceback (most recent call last):
  File "/code/service.py", line 26, in _request
    raise JudgeServiceError(r["data"])
exception.JudgeServiceError
2023-03-21 14:47:23,410 ERROR 
Traceback (most recent call last):
  File "/code/service.py", line 26, in _request
    raise JudgeServiceError(r["data"])
exception.JudgeServiceError

During handling of the above exception, another exception occurred:

Traceback (most recent call last):
  File "/code/service.py", line 42, in <module>
    service.heartbeat()
  File "/code/service.py", line 35, in heartbeat
    self._request(data)
  File "/code/service.py", line 29, in _request
    raise JudgeServiceError("Invalid heartbeat response")
exception.JudgeServiceError
2023-03-21 14:47:28,641 ERROR Heartbeat failed, response is {
    "error": "error",
    "data": "Invalid token"
}
Traceback (most recent call last):
  File "/code/service.py", line 26, in _request
    raise JudgeServiceError(r["data"])
exception.JudgeServiceError
2023-03-21 14:47:28,642 ERROR 
Traceback (most recent call last):
  File "/code/service.py", line 26, in _request
    raise JudgeServiceError(r["data"])
exception.JudgeServiceError

During handling of the above exception, another exception occurred:

Traceback (most recent call last):
  File "/code/service.py", line 42, in <module>
    service.heartbeat()
  File "/code/service.py", line 35, in heartbeat
    self._request(data)
  File "/code/service.py", line 29, in _request
    raise JudgeServiceError("Invalid heartbeat response")
exception.JudgeServiceError
2023-03-21 14:47:33,838 ERROR Heartbeat failed, response is {
    "error": "error",
    "data": "Invalid token"
}
Traceback (most recent call last):
  File "/code/service.py", line 26, in _request
    raise JudgeServiceError(r["data"])
exception.JudgeServiceError
2023-03-21 14:47:33,838 ERROR 
Traceback (most recent call last):
  File "/code/service.py", line 26, in _request
    raise JudgeServiceError(r["data"])
exception.JudgeServiceError

During handling of the above exception, another exception occurred:

Traceback (most recent call last):
  File "/code/service.py", line 42, in <module>
    service.heartbeat()
  File "/code/service.py", line 35, in heartbeat
    self._request(data)
  File "/code/service.py", line 29, in _request
    raise JudgeServiceError("Invalid heartbeat response")
exception.JudgeServiceError
2023-03-21 14:47:39,059 ERROR Heartbeat failed, response is {
    "error": "error",
    "data": "Invalid token"
}
Traceback (most recent call last):
  File "/code/service.py", line 26, in _request
    raise JudgeServiceError(r["data"])
exception.JudgeServiceError
2023-03-21 14:47:39,059 ERROR 
Traceback (most recent call last):
  File "/code/service.py", line 26, in _request
    raise JudgeServiceError(r["data"])
exception.JudgeServiceError

During handling of the above exception, another exception occurred:

Traceback (most recent call last):
  File "/code/service.py", line 42, in <module>
    service.heartbeat()
  File "/code/service.py", line 35, in heartbeat
    self._request(data)
  File "/code/service.py", line 29, in _request
    raise JudgeServiceError("Invalid heartbeat response")
exception.JudgeServiceError
2023-03-21 14:47:44,248 ERROR Heartbeat failed, response is {
    "error": "error",
    "data": "Invalid token"
}
Traceback (most recent call last):
  File "/code/service.py", line 26, in _request
    raise JudgeServiceError(r["data"])
exception.JudgeServiceError
2023-03-21 14:47:44,249 ERROR 
Traceback (most recent call last):
  File "/code/service.py", line 26, in _request
    raise JudgeServiceError(r["data"])
exception.JudgeServiceError

During handling of the above exception, another exception occurred:

Traceback (most recent call last):
  File "/code/service.py", line 42, in <module>
    service.heartbeat()
  File "/code/service.py", line 35, in heartbeat
    self._request(data)
  File "/code/service.py", line 29, in _request
    raise JudgeServiceError("Invalid heartbeat response")
exception.JudgeServiceError
2023-03-21 14:47:49,453 ERROR Heartbeat failed, response is {
    "error": "error",
    "data": "Invalid token"
}
Traceback (most recent call last):
  File "/code/service.py", line 26, in _request
    raise JudgeServiceError(r["data"])
exception.JudgeServiceError
2023-03-21 14:47:49,453 ERROR 
Traceback (most recent call last):
  File "/code/service.py", line 26, in _request
    raise JudgeServiceError(r["data"])
exception.JudgeServiceError

During handling of the above exception, another exception occurred:

Traceback (most recent call last):
  File "/code/service.py", line 42, in <module>
    service.heartbeat()
  File "/code/service.py", line 35, in heartbeat
    self._request(data)
  File "/code/service.py", line 29, in _request
    raise JudgeServiceError("Invalid heartbeat response")
exception.JudgeServiceError
2023-03-21 14:47:54,646 ERROR Heartbeat failed, response is {
    "error": "error",
    "data": "Invalid token"
}
Traceback (most recent call last):
  File "/code/service.py", line 26, in _request
    raise JudgeServiceError(r["data"])
exception.JudgeServiceError
2023-03-21 14:47:54,646 ERROR 
Traceback (most recent call last):
  File "/code/service.py", line 26, in _request
    raise JudgeServiceError(r["data"])
exception.JudgeServiceError

During handling of the above exception, another exception occurred:

Traceback (most recent call last):
  File "/code/service.py", line 42, in <module>
    service.heartbeat()
  File "/code/service.py", line 35, in heartbeat
    self._request(data)
  File "/code/service.py", line 29, in _request
    raise JudgeServiceError("Invalid heartbeat response")
exception.JudgeServiceError
2023-03-21 14:47:59,853 ERROR Heartbeat failed, response is {
    "error": "error",
    "data": "Invalid token"
}
Traceback (most recent call last):
  File "/code/service.py", line 26, in _request
    raise JudgeServiceError(r["data"])
exception.JudgeServiceError
2023-03-21 14:47:59,853 ERROR 
Traceback (most recent call last):
  File "/code/service.py", line 26, in _request
    raise JudgeServiceError(r["data"])
exception.JudgeServiceError

During handling of the above exception, another exception occurred:

Traceback (most recent call last):
  File "/code/service.py", line 42, in <module>
    service.heartbeat()
  File "/code/service.py", line 35, in heartbeat
    self._request(data)
  File "/code/service.py", line 29, in _request
    raise JudgeServiceError("Invalid heartbeat response")
exception.JudgeServiceError
2023-03-21 14:48:05,067 ERROR Heartbeat failed, response is {
    "error": "error",
    "data": "Invalid token"
}
Traceback (most recent call last):
  File "/code/service.py", line 26, in _request
    raise JudgeServiceError(r["data"])
exception.JudgeServiceError
2023-03-21 14:48:05,068 ERROR 
Traceback (most recent call last):
  File "/code/service.py", line 26, in _request
    raise JudgeServiceError(r["data"])
exception.JudgeServiceError

During handling of the above exception, another exception occurred:

Traceback (most recent call last):
  File "/code/service.py", line 42, in <module>
    service.heartbeat()
  File "/code/service.py", line 35, in heartbeat
    self._request(data)
  File "/code/service.py", line 29, in _request
    raise JudgeServiceError("Invalid heartbeat response")
exception.JudgeServiceError
2023-03-21 14:48:10,297 ERROR Heartbeat failed, response is {
    "error": "error",
    "data": "Invalid token"
}
Traceback (most recent call last):
  File "/code/service.py", line 26, in _request
    raise JudgeServiceError(r["data"])
exception.JudgeServiceError
2023-03-21 14:48:10,297 ERROR 
Traceback (most recent call last):
  File "/code/service.py", line 26, in _request
    raise JudgeServiceError(r["data"])
exception.JudgeServiceError

During handling of the above exception, another exception occurred:

Traceback (most recent call last):
  File "/code/service.py", line 42, in <module>
    service.heartbeat()
  File "/code/service.py", line 35, in heartbeat
    self._request(data)
  File "/code/service.py", line 29, in _request
    raise JudgeServiceError("Invalid heartbeat response")
exception.JudgeServiceError
2023-03-21 14:48:15,492 ERROR Heartbeat failed, response is {
    "error": "error",
    "data": "Invalid token"
}
Traceback (most recent call last):
  File "/code/service.py", line 26, in _request
    raise JudgeServiceError(r["data"])
exception.JudgeServiceError
2023-03-21 14:48:15,492 ERROR 
Traceback (most recent call last):
  File "/code/service.py", line 26, in _request
    raise JudgeServiceError(r["data"])
exception.JudgeServiceError

During handling of the above exception, another exception occurred:

Traceback (most recent call last):
  File "/code/service.py", line 42, in <module>
    service.heartbeat()
  File "/code/service.py", line 35, in heartbeat
    self._request(data)
  File "/code/service.py", line 29, in _request
    raise JudgeServiceError("Invalid heartbeat response")
exception.JudgeServiceError
2023-03-21 14:48:20,714 ERROR Heartbeat failed, response is {
    "error": "error",
    "data": "Invalid token"
}
Traceback (most recent call last):
  File "/code/service.py", line 26, in _request
    raise JudgeServiceError(r["data"])
exception.JudgeServiceError
2023-03-21 14:48:20,715 ERROR 
Traceback (most recent call last):
  File "/code/service.py", line 26, in _request
    raise JudgeServiceError(r["data"])
exception.JudgeServiceError

During handling of the above exception, another exception occurred:

Traceback (most recent call last):
  File "/code/service.py", line 42, in <module>
    service.heartbeat()
  File "/code/service.py", line 35, in heartbeat
    self._request(data)
  File "/code/service.py", line 29, in _request
    raise JudgeServiceError("Invalid heartbeat response")
exception.JudgeServiceError
2023-03-21 14:48:25,915 ERROR Heartbeat failed, response is {
    "error": "error",
    "data": "Invalid token"
}
Traceback (most recent call last):
  File "/code/service.py", line 26, in _request
    raise JudgeServiceError(r["data"])
exception.JudgeServiceError
2023-03-21 14:48:25,915 ERROR 
Traceback (most recent call last):
  File "/code/service.py", line 26, in _request
    raise JudgeServiceError(r["data"])
exception.JudgeServiceError

During handling of the above exception, another exception occurred:

Traceback (most recent call last):
  File "/code/service.py", line 42, in <module>
    service.heartbeat()
  File "/code/service.py", line 35, in heartbeat
    self._request(data)
  File "/code/service.py", line 29, in _request
    raise JudgeServiceError("Invalid heartbeat response")
exception.JudgeServiceError
2023-03-21 14:48:31,127 ERROR Heartbeat failed, response is {
    "error": "error",
    "data": "Invalid token"
}
Traceback (most recent call last):
  File "/code/service.py", line 26, in _request
    raise JudgeServiceError(r["data"])
exception.JudgeServiceError
2023-03-21 14:48:31,127 ERROR 
Traceback (most recent call last):
  File "/code/service.py", line 26, in _request
    raise JudgeServiceError(r["data"])
exception.JudgeServiceError

During handling of the above exception, another exception occurred:

Traceback (most recent call last):
  File "/code/service.py", line 42, in <module>
    service.heartbeat()
  File "/code/service.py", line 35, in heartbeat
    self._request(data)
  File "/code/service.py", line 29, in _request
    raise JudgeServiceError("Invalid heartbeat response")
exception.JudgeServiceError
2023-03-21 14:48:36,553 ERROR Heartbeat failed, response is {
    "error": "error",
    "data": "Invalid token"
}
Traceback (most recent call last):
  File "/code/service.py", line 26, in _request
    raise JudgeServiceError(r["data"])
exception.JudgeServiceError
2023-03-21 14:48:36,553 ERROR 
Traceback (most recent call last):
  File "/code/service.py", line 26, in _request
    raise JudgeServiceError(r["data"])
exception.JudgeServiceError

During handling of the above exception, another exception occurred:

Traceback (most recent call last):
  File "/code/service.py", line 42, in <module>
    service.heartbeat()
  File "/code/service.py", line 35, in heartbeat
    self._request(data)
  File "/code/service.py", line 29, in _request
    raise JudgeServiceError("Invalid heartbeat response")
exception.JudgeServiceError
2023-03-21 14:48:41,757 ERROR Heartbeat failed, response is {
    "error": "error",
    "data": "Invalid token"
}
Traceback (most recent call last):
  File "/code/service.py", line 26, in _request
    raise JudgeServiceError(r["data"])
exception.JudgeServiceError
2023-03-21 14:48:41,757 ERROR 
Traceback (most recent call last):
  File "/code/service.py", line 26, in _request
    raise JudgeServiceError(r["data"])
exception.JudgeServiceError

During handling of the above exception, another exception occurred:

Traceback (most recent call last):
  File "/code/service.py", line 42, in <module>
    service.heartbeat()
  File "/code/service.py", line 35, in heartbeat
    self._request(data)
  File "/code/service.py", line 29, in _request
    raise JudgeServiceError("Invalid heartbeat response")
exception.JudgeServiceError
2023-03-21 14:48:46,978 ERROR Heartbeat failed, response is {
    "error": "error",
    "data": "Invalid token"
}
Traceback (most recent call last):
  File "/code/service.py", line 26, in _request
    raise JudgeServiceError(r["data"])
exception.JudgeServiceError
2023-03-21 14:48:46,978 ERROR 
Traceback (most recent call last):
  File "/code/service.py", line 26, in _request
    raise JudgeServiceError(r["data"])
exception.JudgeServiceError

During handling of the above exception, another exception occurred:

Traceback (most recent call last):
  File "/code/service.py", line 42, in <module>
    service.heartbeat()
  File "/code/service.py", line 35, in heartbeat
    self._request(data)
  File "/code/service.py", line 29, in _request
    raise JudgeServiceError("Invalid heartbeat response")
exception.JudgeServiceError
2023-03-21 14:48:52,194 ERROR Heartbeat failed, response is {
    "error": "error",
    "data": "Invalid token"
}
Traceback (most recent call last):
  File "/code/service.py", line 26, in _request
    raise JudgeServiceError(r["data"])
exception.JudgeServiceError
2023-03-21 14:48:52,194 ERROR 
Traceback (most recent call last):
  File "/code/service.py", line 26, in _request
    raise JudgeServiceError(r["data"])
exception.JudgeServiceError

During handling of the above exception, another exception occurred:

Traceback (most recent call last):
  File "/code/service.py", line 42, in <module>
    service.heartbeat()
  File "/code/service.py", line 35, in heartbeat
    self._request(data)
  File "/code/service.py", line 29, in _request
    raise JudgeServiceError("Invalid heartbeat response")
exception.JudgeServiceError
2023-03-21 14:48:57,403 ERROR Heartbeat failed, response is {
    "error": "error",
    "data": "Invalid token"
}
Traceback (most recent call last):
  File "/code/service.py", line 26, in _request
    raise JudgeServiceError(r["data"])
exception.JudgeServiceError
2023-03-21 14:48:57,403 ERROR 
Traceback (most recent call last):
  File "/code/service.py", line 26, in _request
    raise JudgeServiceError(r["data"])
exception.JudgeServiceError

During handling of the above exception, another exception occurred:

Traceback (most recent call last):
  File "/code/service.py", line 42, in <module>
    service.heartbeat()
  File "/code/service.py", line 35, in heartbeat
    self._request(data)
  File "/code/service.py", line 29, in _request
    raise JudgeServiceError("Invalid heartbeat response")
exception.JudgeServiceError
2023-03-21 14:49:02,603 ERROR Heartbeat failed, response is {
    "error": "error",
    "data": "Invalid token"
}
Traceback (most recent call last):
  File "/code/service.py", line 26, in _request
    raise JudgeServiceError(r["data"])
exception.JudgeServiceError
2023-03-21 14:49:02,603 ERROR 
Traceback (most recent call last):
  File "/code/service.py", line 26, in _request
    raise JudgeServiceError(r["data"])
exception.JudgeServiceError

During handling of the above exception, another exception occurred:

Traceback (most recent call last):
  File "/code/service.py", line 42, in <module>
    service.heartbeat()
  File "/code/service.py", line 35, in heartbeat
    self._request(data)
  File "/code/service.py", line 29, in _request
    raise JudgeServiceError("Invalid heartbeat response")
exception.JudgeServiceError
2023-03-21 14:49:07,820 ERROR Heartbeat failed, response is {
    "error": "error",
    "data": "Invalid token"
}
Traceback (most recent call last):
  File "/code/service.py", line 26, in _request
    raise JudgeServiceError(r["data"])
exception.JudgeServiceError
2023-03-21 14:49:07,820 ERROR 
Traceback (most recent call last):
  File "/code/service.py", line 26, in _request
    raise JudgeServiceError(r["data"])
exception.JudgeServiceError

During handling of the above exception, another exception occurred:

Traceback (most recent call last):
  File "/code/service.py", line 42, in <module>
    service.heartbeat()
  File "/code/service.py", line 35, in heartbeat
    self._request(data)
  File "/code/service.py", line 29, in _request
    raise JudgeServiceError("Invalid heartbeat response")
exception.JudgeServiceError
2023-03-21 14:49:13,023 ERROR Heartbeat failed, response is {
    "error": "error",
    "data": "Invalid token"
}
Traceback (most recent call last):
  File "/code/service.py", line 26, in _request
    raise JudgeServiceError(r["data"])
exception.JudgeServiceError
2023-03-21 14:49:13,023 ERROR 
Traceback (most recent call last):
  File "/code/service.py", line 26, in _request
    raise JudgeServiceError(r["data"])
exception.JudgeServiceError

During handling of the above exception, another exception occurred:

Traceback (most recent call last):
  File "/code/service.py", line 42, in <module>
    service.heartbeat()
  File "/code/service.py", line 35, in heartbeat
    self._request(data)
  File "/code/service.py", line 29, in _request
    raise JudgeServiceError("Invalid heartbeat response")
exception.JudgeServiceError
2023-03-21 14:49:18,222 ERROR Heartbeat failed, response is {
    "error": "error",
    "data": "Invalid token"
}
Traceback (most recent call last):
  File "/code/service.py", line 26, in _request
    raise JudgeServiceError(r["data"])
exception.JudgeServiceError
2023-03-21 14:49:18,222 ERROR 
Traceback (most recent call last):
  File "/code/service.py", line 26, in _request
    raise JudgeServiceError(r["data"])
exception.JudgeServiceError

During handling of the above exception, another exception occurred:

Traceback (most recent call last):
  File "/code/service.py", line 42, in <module>
    service.heartbeat()
  File "/code/service.py", line 35, in heartbeat
    self._request(data)
  File "/code/service.py", line 29, in _request
    raise JudgeServiceError("Invalid heartbeat response")
exception.JudgeServiceError
2023-03-21 14:49:23,435 ERROR Heartbeat failed, response is {
    "error": "error",
    "data": "Invalid token"
}
Traceback (most recent call last):
  File "/code/service.py", line 26, in _request
    raise JudgeServiceError(r["data"])
exception.JudgeServiceError
2023-03-21 14:49:23,436 ERROR 
Traceback (most recent call last):
  File "/code/service.py", line 26, in _request
    raise JudgeServiceError(r["data"])
exception.JudgeServiceError

During handling of the above exception, another exception occurred:

Traceback (most recent call last):
  File "/code/service.py", line 42, in <module>
    service.heartbeat()
  File "/code/service.py", line 35, in heartbeat
    self._request(data)
  File "/code/service.py", line 29, in _request
    raise JudgeServiceError("Invalid heartbeat response")
exception.JudgeServiceError
2023-03-21 14:49:28,672 ERROR Heartbeat failed, response is {
    "error": "error",
    "data": "Invalid token"
}
Traceback (most recent call last):
  File "/code/service.py", line 26, in _request
    raise JudgeServiceError(r["data"])
exception.JudgeServiceError
2023-03-21 14:49:28,673 ERROR 
Traceback (most recent call last):
  File "/code/service.py", line 26, in _request
    raise JudgeServiceError(r["data"])
exception.JudgeServiceError

During handling of the above exception, another exception occurred:

Traceback (most recent call last):
  File "/code/service.py", line 42, in <module>
    service.heartbeat()
  File "/code/service.py", line 35, in heartbeat
    self._request(data)
  File "/code/service.py", line 29, in _request
    raise JudgeServiceError("Invalid heartbeat response")
exception.JudgeServiceError
2023-03-21 14:49:33,876 ERROR Heartbeat failed, response is {
    "error": "error",
    "data": "Invalid token"
}
Traceback (most recent call last):
  File "/code/service.py", line 26, in _request
    raise JudgeServiceError(r["data"])
exception.JudgeServiceError
2023-03-21 14:49:33,877 ERROR 
Traceback (most recent call last):
  File "/code/service.py", line 26, in _request
    raise JudgeServiceError(r["data"])
exception.JudgeServiceError

During handling of the above exception, another exception occurred:

Traceback (most recent call last):
  File "/code/service.py", line 42, in <module>
    service.heartbeat()
  File "/code/service.py", line 35, in heartbeat
    self._request(data)
  File "/code/service.py", line 29, in _request
    raise JudgeServiceError("Invalid heartbeat response")
exception.JudgeServiceError
2023-03-21 14:49:39,064 ERROR Heartbeat failed, response is {
    "error": "error",
    "data": "Invalid token"
}
Traceback (most recent call last):
  File "/code/service.py", line 26, in _request
    raise JudgeServiceError(r["data"])
exception.JudgeServiceError
2023-03-21 14:49:39,064 ERROR 
Traceback (most recent call last):
  File "/code/service.py", line 26, in _request
    raise JudgeServiceError(r["data"])
exception.JudgeServiceError

During handling of the above exception, another exception occurred:

Traceback (most recent call last):
  File "/code/service.py", line 42, in <module>
    service.heartbeat()
  File "/code/service.py", line 35, in heartbeat
    self._request(data)
  File "/code/service.py", line 29, in _request
    raise JudgeServiceError("Invalid heartbeat response")
exception.JudgeServiceError
2023-03-21 14:49:44,269 ERROR Heartbeat failed, response is {
    "error": "error",
    "data": "Invalid token"
}
Traceback (most recent call last):
  File "/code/service.py", line 26, in _request
    raise JudgeServiceError(r["data"])
exception.JudgeServiceError
2023-03-21 14:49:44,269 ERROR 
Traceback (most recent call last):
  File "/code/service.py", line 26, in _request
    raise JudgeServiceError(r["data"])
exception.JudgeServiceError

During handling of the above exception, another exception occurred:

Traceback (most recent call last):
  File "/code/service.py", line 42, in <module>
    service.heartbeat()
  File "/code/service.py", line 35, in heartbeat
    self._request(data)
  File "/code/service.py", line 29, in _request
    raise JudgeServiceError("Invalid heartbeat response")
exception.JudgeServiceError
2023-03-21 14:49:49,462 ERROR Heartbeat failed, response is {
    "error": "error",
    "data": "Invalid token"
}
Traceback (most recent call last):
  File "/code/service.py", line 26, in _request
    raise JudgeServiceError(r["data"])
exception.JudgeServiceError
2023-03-21 14:49:49,462 ERROR 
Traceback (most recent call last):
  File "/code/service.py", line 26, in _request
    raise JudgeServiceError(r["data"])
exception.JudgeServiceError

During handling of the above exception, another exception occurred:

Traceback (most recent call last):
  File "/code/service.py", line 42, in <module>
    service.heartbeat()
  File "/code/service.py", line 35, in heartbeat
    self._request(data)
  File "/code/service.py", line 29, in _request
    raise JudgeServiceError("Invalid heartbeat response")
exception.JudgeServiceError
2023-03-21 14:49:54,661 ERROR Heartbeat failed, response is {
    "error": "error",
    "data": "Invalid token"
}
Traceback (most recent call last):
  File "/code/service.py", line 26, in _request
    raise JudgeServiceError(r["data"])
exception.JudgeServiceError
2023-03-21 14:49:54,661 ERROR 
Traceback (most recent call last):
  File "/code/service.py", line 26, in _request
    raise JudgeServiceError(r["data"])
exception.JudgeServiceError

During handling of the above exception, another exception occurred:

Traceback (most recent call last):
  File "/code/service.py", line 42, in <module>
    service.heartbeat()
  File "/code/service.py", line 35, in heartbeat
    self._request(data)
  File "/code/service.py", line 29, in _request
    raise JudgeServiceError("Invalid heartbeat response")
exception.JudgeServiceError
2023-03-21 14:49:59,859 ERROR Heartbeat failed, response is {
    "error": "error",
    "data": "Invalid token"
}
Traceback (most recent call last):
  File "/code/service.py", line 26, in _request
    raise JudgeServiceError(r["data"])
exception.JudgeServiceError
2023-03-21 14:49:59,860 ERROR 
Traceback (most recent call last):
  File "/code/service.py", line 26, in _request
    raise JudgeServiceError(r["data"])
exception.JudgeServiceError

During handling of the above exception, another exception occurred:

Traceback (most recent call last):
  File "/code/service.py", line 42, in <module>
    service.heartbeat()
  File "/code/service.py", line 35, in heartbeat
    self._request(data)
  File "/code/service.py", line 29, in _request
    raise JudgeServiceError("Invalid heartbeat response")
exception.JudgeServiceError
2023-03-21 14:50:05,053 ERROR Heartbeat failed, response is {
    "error": "error",
    "data": "Invalid token"
}
Traceback (most recent call last):
  File "/code/service.py", line 26, in _request
    raise JudgeServiceError(r["data"])
exception.JudgeServiceError
2023-03-21 14:50:05,053 ERROR 
Traceback (most recent call last):
  File "/code/service.py", line 26, in _request
    raise JudgeServiceError(r["data"])
exception.JudgeServiceError

During handling of the above exception, another exception occurred:

Traceback (most recent call last):
  File "/code/service.py", line 42, in <module>
    service.heartbeat()
  File "/code/service.py", line 35, in heartbeat
    self._request(data)
  File "/code/service.py", line 29, in _request
    raise JudgeServiceError("Invalid heartbeat response")
exception.JudgeServiceError
2023-03-21 14:50:10,250 ERROR Heartbeat failed, response is {
    "error": "error",
    "data": "Invalid token"
}
Traceback (most recent call last):
  File "/code/service.py", line 26, in _request
    raise JudgeServiceError(r["data"])
exception.JudgeServiceError
2023-03-21 14:50:10,251 ERROR 
Traceback (most recent call last):
  File "/code/service.py", line 26, in _request
    raise JudgeServiceError(r["data"])
exception.JudgeServiceError

During handling of the above exception, another exception occurred:

Traceback (most recent call last):
  File "/code/service.py", line 42, in <module>
    service.heartbeat()
  File "/code/service.py", line 35, in heartbeat
    self._request(data)
  File "/code/service.py", line 29, in _request
    raise JudgeServiceError("Invalid heartbeat response")
exception.JudgeServiceError
2023-03-21 14:50:15,453 ERROR HTTPConnectionPool(host='oj-backend', port=8000): Max retries exceeded with url: /api/judge_server_heartbeat/ (Caused by NewConnectionError('<urllib3.connection.HTTPConnection object at 0x7fa69187c860>: Failed to establish a new connection: [Errno 111] Connection refused',))
Traceback (most recent call last):
  File "/usr/local/lib/python3.6/dist-packages/urllib3/connection.py", line 175, in _new_conn
    (self._dns_host, self.port), self.timeout, **extra_kw
  File "/usr/local/lib/python3.6/dist-packages/urllib3/util/connection.py", line 96, in create_connection
    raise err
  File "/usr/local/lib/python3.6/dist-packages/urllib3/util/connection.py", line 86, in create_connection
    sock.connect(sa)
ConnectionRefusedError: [Errno 111] Connection refused

During handling of the above exception, another exception occurred:

Traceback (most recent call last):
  File "/usr/local/lib/python3.6/dist-packages/urllib3/connectionpool.py", line 706, in urlopen
    chunked=chunked,
  File "/usr/local/lib/python3.6/dist-packages/urllib3/connectionpool.py", line 394, in _make_request
    conn.request(method, url, **httplib_request_kw)
  File "/usr/local/lib/python3.6/dist-packages/urllib3/connection.py", line 239, in request
    super(HTTPConnection, self).request(method, url, body=body, headers=headers)
  File "/usr/lib/python3.6/http/client.py", line 1281, in request
    self._send_request(method, url, body, headers, encode_chunked)
  File "/usr/lib/python3.6/http/client.py", line 1327, in _send_request
    self.endheaders(body, encode_chunked=encode_chunked)
  File "/usr/lib/python3.6/http/client.py", line 1276, in endheaders
    self._send_output(message_body, encode_chunked=encode_chunked)
  File "/usr/lib/python3.6/http/client.py", line 1042, in _send_output
    self.send(msg)
  File "/usr/lib/python3.6/http/client.py", line 980, in send
    self.connect()
  File "/usr/local/lib/python3.6/dist-packages/urllib3/connection.py", line 205, in connect
    conn = self._new_conn()
  File "/usr/local/lib/python3.6/dist-packages/urllib3/connection.py", line 187, in _new_conn
    self, "Failed to establish a new connection: %s" % e
urllib3.exceptions.NewConnectionError: <urllib3.connection.HTTPConnection object at 0x7fa69187c860>: Failed to establish a new connection: [Errno 111] Connection refused

During handling of the above exception, another exception occurred:

Traceback (most recent call last):
  File "/usr/local/lib/python3.6/dist-packages/requests/adapters.py", line 449, in send
    timeout=timeout
  File "/usr/local/lib/python3.6/dist-packages/urllib3/connectionpool.py", line 756, in urlopen
    method, url, error=e, _pool=self, _stacktrace=sys.exc_info()[2]
  File "/usr/local/lib/python3.6/dist-packages/urllib3/util/retry.py", line 574, in increment
    raise MaxRetryError(_pool, url, error or ResponseError(cause))
urllib3.exceptions.MaxRetryError: HTTPConnectionPool(host='oj-backend', port=8000): Max retries exceeded with url: /api/judge_server_heartbeat/ (Caused by NewConnectionError('<urllib3.connection.HTTPConnection object at 0x7fa69187c860>: Failed to establish a new connection: [Errno 111] Connection refused',))

During handling of the above exception, another exception occurred:

Traceback (most recent call last):
  File "/code/service.py", line 19, in _request
    "Content-Type": "application/json"}, timeout=5).text
  File "/usr/local/lib/python3.6/dist-packages/requests/api.py", line 117, in post
    return request('post', url, data=data, json=json, **kwargs)
  File "/usr/local/lib/python3.6/dist-packages/requests/api.py", line 61, in request
    return session.request(method=method, url=url, **kwargs)
  File "/usr/local/lib/python3.6/dist-packages/requests/sessions.py", line 542, in request
    resp = self.send(prep, **send_kwargs)
  File "/usr/local/lib/python3.6/dist-packages/requests/sessions.py", line 655, in send
    r = adapter.send(request, **kwargs)
  File "/usr/local/lib/python3.6/dist-packages/requests/adapters.py", line 516, in send
    raise ConnectionError(e, request=request)
requests.exceptions.ConnectionError: HTTPConnectionPool(host='oj-backend', port=8000): Max retries exceeded with url: /api/judge_server_heartbeat/ (Caused by NewConnectionError('<urllib3.connection.HTTPConnection object at 0x7fa69187c860>: Failed to establish a new connection: [Errno 111] Connection refused',))
2023-03-21 14:50:15,530 ERROR 
Traceback (most recent call last):
  File "/usr/local/lib/python3.6/dist-packages/urllib3/connection.py", line 175, in _new_conn
    (self._dns_host, self.port), self.timeout, **extra_kw
  File "/usr/local/lib/python3.6/dist-packages/urllib3/util/connection.py", line 96, in create_connection
    raise err
  File "/usr/local/lib/python3.6/dist-packages/urllib3/util/connection.py", line 86, in create_connection
    sock.connect(sa)
ConnectionRefusedError: [Errno 111] Connection refused

During handling of the above exception, another exception occurred:

Traceback (most recent call last):
  File "/usr/local/lib/python3.6/dist-packages/urllib3/connectionpool.py", line 706, in urlopen
    chunked=chunked,
  File "/usr/local/lib/python3.6/dist-packages/urllib3/connectionpool.py", line 394, in _make_request
    conn.request(method, url, **httplib_request_kw)
  File "/usr/local/lib/python3.6/dist-packages/urllib3/connection.py", line 239, in request
    super(HTTPConnection, self).request(method, url, body=body, headers=headers)
  File "/usr/lib/python3.6/http/client.py", line 1281, in request
    self._send_request(method, url, body, headers, encode_chunked)
  File "/usr/lib/python3.6/http/client.py", line 1327, in _send_request
    self.endheaders(body, encode_chunked=encode_chunked)
  File "/usr/lib/python3.6/http/client.py", line 1276, in endheaders
    self._send_output(message_body, encode_chunked=encode_chunked)
  File "/usr/lib/python3.6/http/client.py", line 1042, in _send_output
    self.send(msg)
  File "/usr/lib/python3.6/http/client.py", line 980, in send
    self.connect()
  File "/usr/local/lib/python3.6/dist-packages/urllib3/connection.py", line 205, in connect
    conn = self._new_conn()
  File "/usr/local/lib/python3.6/dist-packages/urllib3/connection.py", line 187, in _new_conn
    self, "Failed to establish a new connection: %s" % e
urllib3.exceptions.NewConnectionError: <urllib3.connection.HTTPConnection object at 0x7fa69187c860>: Failed to establish a new connection: [Errno 111] Connection refused

During handling of the above exception, another exception occurred:

Traceback (most recent call last):
  File "/usr/local/lib/python3.6/dist-packages/requests/adapters.py", line 449, in send
    timeout=timeout
  File "/usr/local/lib/python3.6/dist-packages/urllib3/connectionpool.py", line 756, in urlopen
    method, url, error=e, _pool=self, _stacktrace=sys.exc_info()[2]
  File "/usr/local/lib/python3.6/dist-packages/urllib3/util/retry.py", line 574, in increment
    raise MaxRetryError(_pool, url, error or ResponseError(cause))
urllib3.exceptions.MaxRetryError: HTTPConnectionPool(host='oj-backend', port=8000): Max retries exceeded with url: /api/judge_server_heartbeat/ (Caused by NewConnectionError('<urllib3.connection.HTTPConnection object at 0x7fa69187c860>: Failed to establish a new connection: [Errno 111] Connection refused',))

During handling of the above exception, another exception occurred:

Traceback (most recent call last):
  File "/code/service.py", line 19, in _request
    "Content-Type": "application/json"}, timeout=5).text
  File "/usr/local/lib/python3.6/dist-packages/requests/api.py", line 117, in post
    return request('post', url, data=data, json=json, **kwargs)
  File "/usr/local/lib/python3.6/dist-packages/requests/api.py", line 61, in request
    return session.request(method=method, url=url, **kwargs)
  File "/usr/local/lib/python3.6/dist-packages/requests/sessions.py", line 542, in request
    resp = self.send(prep, **send_kwargs)
  File "/usr/local/lib/python3.6/dist-packages/requests/sessions.py", line 655, in send
    r = adapter.send(request, **kwargs)
  File "/usr/local/lib/python3.6/dist-packages/requests/adapters.py", line 516, in send
    raise ConnectionError(e, request=request)
requests.exceptions.ConnectionError: HTTPConnectionPool(host='oj-backend', port=8000): Max retries exceeded with url: /api/judge_server_heartbeat/ (Caused by NewConnectionError('<urllib3.connection.HTTPConnection object at 0x7fa69187c860>: Failed to establish a new connection: [Errno 111] Connection refused',))

During handling of the above exception, another exception occurred:

Traceback (most recent call last):
  File "/code/service.py", line 42, in <module>
    service.heartbeat()
  File "/code/service.py", line 35, in heartbeat
    self._request(data)
  File "/code/service.py", line 22, in _request
    raise JudgeServiceError("Heartbeat request failed")
exception.JudgeServiceError
2023-03-21 14:50:20,745 ERROR HTTPConnectionPool(host='oj-backend', port=8000): Max retries exceeded with url: /api/judge_server_heartbeat/ (Caused by NewConnectionError('<urllib3.connection.HTTPConnection object at 0x7fbae6fcd860>: Failed to establish a new connection: [Errno 111] Connection refused',))
Traceback (most recent call last):
  File "/usr/local/lib/python3.6/dist-packages/urllib3/connection.py", line 175, in _new_conn
    (self._dns_host, self.port), self.timeout, **extra_kw
  File "/usr/local/lib/python3.6/dist-packages/urllib3/util/connection.py", line 96, in create_connection
    raise err
  File "/usr/local/lib/python3.6/dist-packages/urllib3/util/connection.py", line 86, in create_connection
    sock.connect(sa)
ConnectionRefusedError: [Errno 111] Connection refused

During handling of the above exception, another exception occurred:

Traceback (most recent call last):
  File "/usr/local/lib/python3.6/dist-packages/urllib3/connectionpool.py", line 706, in urlopen
    chunked=chunked,
  File "/usr/local/lib/python3.6/dist-packages/urllib3/connectionpool.py", line 394, in _make_request
    conn.request(method, url, **httplib_request_kw)
  File "/usr/local/lib/python3.6/dist-packages/urllib3/connection.py", line 239, in request
    super(HTTPConnection, self).request(method, url, body=body, headers=headers)
  File "/usr/lib/python3.6/http/client.py", line 1281, in request
    self._send_request(method, url, body, headers, encode_chunked)
  File "/usr/lib/python3.6/http/client.py", line 1327, in _send_request
    self.endheaders(body, encode_chunked=encode_chunked)
  File "/usr/lib/python3.6/http/client.py", line 1276, in endheaders
    self._send_output(message_body, encode_chunked=encode_chunked)
  File "/usr/lib/python3.6/http/client.py", line 1042, in _send_output
    self.send(msg)
  File "/usr/lib/python3.6/http/client.py", line 980, in send
    self.connect()
  File "/usr/local/lib/python3.6/dist-packages/urllib3/connection.py", line 205, in connect
    conn = self._new_conn()
  File "/usr/local/lib/python3.6/dist-packages/urllib3/connection.py", line 187, in _new_conn
    self, "Failed to establish a new connection: %s" % e
urllib3.exceptions.NewConnectionError: <urllib3.connection.HTTPConnection object at 0x7fbae6fcd860>: Failed to establish a new connection: [Errno 111] Connection refused

During handling of the above exception, another exception occurred:

Traceback (most recent call last):
  File "/usr/local/lib/python3.6/dist-packages/requests/adapters.py", line 449, in send
    timeout=timeout
  File "/usr/local/lib/python3.6/dist-packages/urllib3/connectionpool.py", line 756, in urlopen
    method, url, error=e, _pool=self, _stacktrace=sys.exc_info()[2]
  File "/usr/local/lib/python3.6/dist-packages/urllib3/util/retry.py", line 574, in increment
    raise MaxRetryError(_pool, url, error or ResponseError(cause))
urllib3.exceptions.MaxRetryError: HTTPConnectionPool(host='oj-backend', port=8000): Max retries exceeded with url: /api/judge_server_heartbeat/ (Caused by NewConnectionError('<urllib3.connection.HTTPConnection object at 0x7fbae6fcd860>: Failed to establish a new connection: [Errno 111] Connection refused',))

During handling of the above exception, another exception occurred:

Traceback (most recent call last):
  File "/code/service.py", line 19, in _request
    "Content-Type": "application/json"}, timeout=5).text
  File "/usr/local/lib/python3.6/dist-packages/requests/api.py", line 117, in post
    return request('post', url, data=data, json=json, **kwargs)
  File "/usr/local/lib/python3.6/dist-packages/requests/api.py", line 61, in request
    return session.request(method=method, url=url, **kwargs)
  File "/usr/local/lib/python3.6/dist-packages/requests/sessions.py", line 542, in request
    resp = self.send(prep, **send_kwargs)
  File "/usr/local/lib/python3.6/dist-packages/requests/sessions.py", line 655, in send
    r = adapter.send(request, **kwargs)
  File "/usr/local/lib/python3.6/dist-packages/requests/adapters.py", line 516, in send
    raise ConnectionError(e, request=request)
requests.exceptions.ConnectionError: HTTPConnectionPool(host='oj-backend', port=8000): Max retries exceeded with url: /api/judge_server_heartbeat/ (Caused by NewConnectionError('<urllib3.connection.HTTPConnection object at 0x7fbae6fcd860>: Failed to establish a new connection: [Errno 111] Connection refused',))
2023-03-21 14:50:20,747 ERROR 
Traceback (most recent call last):
  File "/usr/local/lib/python3.6/dist-packages/urllib3/connection.py", line 175, in _new_conn
    (self._dns_host, self.port), self.timeout, **extra_kw
  File "/usr/local/lib/python3.6/dist-packages/urllib3/util/connection.py", line 96, in create_connection
    raise err
  File "/usr/local/lib/python3.6/dist-packages/urllib3/util/connection.py", line 86, in create_connection
    sock.connect(sa)
ConnectionRefusedError: [Errno 111] Connection refused

During handling of the above exception, another exception occurred:

Traceback (most recent call last):
  File "/usr/local/lib/python3.6/dist-packages/urllib3/connectionpool.py", line 706, in urlopen
    chunked=chunked,
  File "/usr/local/lib/python3.6/dist-packages/urllib3/connectionpool.py", line 394, in _make_request
    conn.request(method, url, **httplib_request_kw)
  File "/usr/local/lib/python3.6/dist-packages/urllib3/connection.py", line 239, in request
    super(HTTPConnection, self).request(method, url, body=body, headers=headers)
  File "/usr/lib/python3.6/http/client.py", line 1281, in request
    self._send_request(method, url, body, headers, encode_chunked)
  File "/usr/lib/python3.6/http/client.py", line 1327, in _send_request
    self.endheaders(body, encode_chunked=encode_chunked)
  File "/usr/lib/python3.6/http/client.py", line 1276, in endheaders
    self._send_output(message_body, encode_chunked=encode_chunked)
  File "/usr/lib/python3.6/http/client.py", line 1042, in _send_output
    self.send(msg)
  File "/usr/lib/python3.6/http/client.py", line 980, in send
    self.connect()
  File "/usr/local/lib/python3.6/dist-packages/urllib3/connection.py", line 205, in connect
    conn = self._new_conn()
  File "/usr/local/lib/python3.6/dist-packages/urllib3/connection.py", line 187, in _new_conn
    self, "Failed to establish a new connection: %s" % e
urllib3.exceptions.NewConnectionError: <urllib3.connection.HTTPConnection object at 0x7fbae6fcd860>: Failed to establish a new connection: [Errno 111] Connection refused

During handling of the above exception, another exception occurred:

Traceback (most recent call last):
  File "/usr/local/lib/python3.6/dist-packages/requests/adapters.py", line 449, in send
    timeout=timeout
  File "/usr/local/lib/python3.6/dist-packages/urllib3/connectionpool.py", line 756, in urlopen
    method, url, error=e, _pool=self, _stacktrace=sys.exc_info()[2]
  File "/usr/local/lib/python3.6/dist-packages/urllib3/util/retry.py", line 574, in increment
    raise MaxRetryError(_pool, url, error or ResponseError(cause))
urllib3.exceptions.MaxRetryError: HTTPConnectionPool(host='oj-backend', port=8000): Max retries exceeded with url: /api/judge_server_heartbeat/ (Caused by NewConnectionError('<urllib3.connection.HTTPConnection object at 0x7fbae6fcd860>: Failed to establish a new connection: [Errno 111] Connection refused',))

During handling of the above exception, another exception occurred:

Traceback (most recent call last):
  File "/code/service.py", line 19, in _request
    "Content-Type": "application/json"}, timeout=5).text
  File "/usr/local/lib/python3.6/dist-packages/requests/api.py", line 117, in post
    return request('post', url, data=data, json=json, **kwargs)
  File "/usr/local/lib/python3.6/dist-packages/requests/api.py", line 61, in request
    return session.request(method=method, url=url, **kwargs)
  File "/usr/local/lib/python3.6/dist-packages/requests/sessions.py", line 542, in request
    resp = self.send(prep, **send_kwargs)
  File "/usr/local/lib/python3.6/dist-packages/requests/sessions.py", line 655, in send
    r = adapter.send(request, **kwargs)
  File "/usr/local/lib/python3.6/dist-packages/requests/adapters.py", line 516, in send
    raise ConnectionError(e, request=request)
requests.exceptions.ConnectionError: HTTPConnectionPool(host='oj-backend', port=8000): Max retries exceeded with url: /api/judge_server_heartbeat/ (Caused by NewConnectionError('<urllib3.connection.HTTPConnection object at 0x7fbae6fcd860>: Failed to establish a new connection: [Errno 111] Connection refused',))

During handling of the above exception, another exception occurred:

Traceback (most recent call last):
  File "/code/service.py", line 42, in <module>
    service.heartbeat()
  File "/code/service.py", line 35, in heartbeat
    self._request(data)
  File "/code/service.py", line 22, in _request
    raise JudgeServiceError("Heartbeat request failed")
exception.JudgeServiceError
2023-03-21 15:34:12,222 ERROR HTTPConnectionPool(host='oj-backend', port=8000): Max retries exceeded with url: /api/judge_server_heartbeat/ (Caused by NewConnectionError('<urllib3.connection.HTTPConnection object at 0x7f44c39687f0>: Failed to establish a new connection: [Errno 111] Connection refused',))
Traceback (most recent call last):
  File "/usr/local/lib/python3.6/dist-packages/urllib3/connection.py", line 175, in _new_conn
    (self._dns_host, self.port), self.timeout, **extra_kw
  File "/usr/local/lib/python3.6/dist-packages/urllib3/util/connection.py", line 96, in create_connection
    raise err
  File "/usr/local/lib/python3.6/dist-packages/urllib3/util/connection.py", line 86, in create_connection
    sock.connect(sa)
ConnectionRefusedError: [Errno 111] Connection refused

During handling of the above exception, another exception occurred:

Traceback (most recent call last):
  File "/usr/local/lib/python3.6/dist-packages/urllib3/connectionpool.py", line 706, in urlopen
    chunked=chunked,
  File "/usr/local/lib/python3.6/dist-packages/urllib3/connectionpool.py", line 394, in _make_request
    conn.request(method, url, **httplib_request_kw)
  File "/usr/local/lib/python3.6/dist-packages/urllib3/connection.py", line 239, in request
    super(HTTPConnection, self).request(method, url, body=body, headers=headers)
  File "/usr/lib/python3.6/http/client.py", line 1281, in request
    self._send_request(method, url, body, headers, encode_chunked)
  File "/usr/lib/python3.6/http/client.py", line 1327, in _send_request
    self.endheaders(body, encode_chunked=encode_chunked)
  File "/usr/lib/python3.6/http/client.py", line 1276, in endheaders
    self._send_output(message_body, encode_chunked=encode_chunked)
  File "/usr/lib/python3.6/http/client.py", line 1042, in _send_output
    self.send(msg)
  File "/usr/lib/python3.6/http/client.py", line 980, in send
    self.connect()
  File "/usr/local/lib/python3.6/dist-packages/urllib3/connection.py", line 205, in connect
    conn = self._new_conn()
  File "/usr/local/lib/python3.6/dist-packages/urllib3/connection.py", line 187, in _new_conn
    self, "Failed to establish a new connection: %s" % e
urllib3.exceptions.NewConnectionError: <urllib3.connection.HTTPConnection object at 0x7f44c39687f0>: Failed to establish a new connection: [Errno 111] Connection refused

During handling of the above exception, another exception occurred:

Traceback (most recent call last):
  File "/usr/local/lib/python3.6/dist-packages/requests/adapters.py", line 449, in send
    timeout=timeout
  File "/usr/local/lib/python3.6/dist-packages/urllib3/connectionpool.py", line 756, in urlopen
    method, url, error=e, _pool=self, _stacktrace=sys.exc_info()[2]
  File "/usr/local/lib/python3.6/dist-packages/urllib3/util/retry.py", line 574, in increment
    raise MaxRetryError(_pool, url, error or ResponseError(cause))
urllib3.exceptions.MaxRetryError: HTTPConnectionPool(host='oj-backend', port=8000): Max retries exceeded with url: /api/judge_server_heartbeat/ (Caused by NewConnectionError('<urllib3.connection.HTTPConnection object at 0x7f44c39687f0>: Failed to establish a new connection: [Errno 111] Connection refused',))

During handling of the above exception, another exception occurred:

Traceback (most recent call last):
  File "/code/service.py", line 19, in _request
    "Content-Type": "application/json"}, timeout=5).text
  File "/usr/local/lib/python3.6/dist-packages/requests/api.py", line 117, in post
    return request('post', url, data=data, json=json, **kwargs)
  File "/usr/local/lib/python3.6/dist-packages/requests/api.py", line 61, in request
    return session.request(method=method, url=url, **kwargs)
  File "/usr/local/lib/python3.6/dist-packages/requests/sessions.py", line 542, in request
    resp = self.send(prep, **send_kwargs)
  File "/usr/local/lib/python3.6/dist-packages/requests/sessions.py", line 655, in send
    r = adapter.send(request, **kwargs)
  File "/usr/local/lib/python3.6/dist-packages/requests/adapters.py", line 516, in send
    raise ConnectionError(e, request=request)
requests.exceptions.ConnectionError: HTTPConnectionPool(host='oj-backend', port=8000): Max retries exceeded with url: /api/judge_server_heartbeat/ (Caused by NewConnectionError('<urllib3.connection.HTTPConnection object at 0x7f44c39687f0>: Failed to establish a new connection: [Errno 111] Connection refused',))
2023-03-21 15:34:12,224 ERROR 
Traceback (most recent call last):
  File "/usr/local/lib/python3.6/dist-packages/urllib3/connection.py", line 175, in _new_conn
    (self._dns_host, self.port), self.timeout, **extra_kw
  File "/usr/local/lib/python3.6/dist-packages/urllib3/util/connection.py", line 96, in create_connection
    raise err
  File "/usr/local/lib/python3.6/dist-packages/urllib3/util/connection.py", line 86, in create_connection
    sock.connect(sa)
ConnectionRefusedError: [Errno 111] Connection refused

During handling of the above exception, another exception occurred:

Traceback (most recent call last):
  File "/usr/local/lib/python3.6/dist-packages/urllib3/connectionpool.py", line 706, in urlopen
    chunked=chunked,
  File "/usr/local/lib/python3.6/dist-packages/urllib3/connectionpool.py", line 394, in _make_request
    conn.request(method, url, **httplib_request_kw)
  File "/usr/local/lib/python3.6/dist-packages/urllib3/connection.py", line 239, in request
    super(HTTPConnection, self).request(method, url, body=body, headers=headers)
  File "/usr/lib/python3.6/http/client.py", line 1281, in request
    self._send_request(method, url, body, headers, encode_chunked)
  File "/usr/lib/python3.6/http/client.py", line 1327, in _send_request
    self.endheaders(body, encode_chunked=encode_chunked)
  File "/usr/lib/python3.6/http/client.py", line 1276, in endheaders
    self._send_output(message_body, encode_chunked=encode_chunked)
  File "/usr/lib/python3.6/http/client.py", line 1042, in _send_output
    self.send(msg)
  File "/usr/lib/python3.6/http/client.py", line 980, in send
    self.connect()
  File "/usr/local/lib/python3.6/dist-packages/urllib3/connection.py", line 205, in connect
    conn = self._new_conn()
  File "/usr/local/lib/python3.6/dist-packages/urllib3/connection.py", line 187, in _new_conn
    self, "Failed to establish a new connection: %s" % e
urllib3.exceptions.NewConnectionError: <urllib3.connection.HTTPConnection object at 0x7f44c39687f0>: Failed to establish a new connection: [Errno 111] Connection refused

During handling of the above exception, another exception occurred:

Traceback (most recent call last):
  File "/usr/local/lib/python3.6/dist-packages/requests/adapters.py", line 449, in send
    timeout=timeout
  File "/usr/local/lib/python3.6/dist-packages/urllib3/connectionpool.py", line 756, in urlopen
    method, url, error=e, _pool=self, _stacktrace=sys.exc_info()[2]
  File "/usr/local/lib/python3.6/dist-packages/urllib3/util/retry.py", line 574, in increment
    raise MaxRetryError(_pool, url, error or ResponseError(cause))
urllib3.exceptions.MaxRetryError: HTTPConnectionPool(host='oj-backend', port=8000): Max retries exceeded with url: /api/judge_server_heartbeat/ (Caused by NewConnectionError('<urllib3.connection.HTTPConnection object at 0x7f44c39687f0>: Failed to establish a new connection: [Errno 111] Connection refused',))

During handling of the above exception, another exception occurred:

Traceback (most recent call last):
  File "/code/service.py", line 19, in _request
    "Content-Type": "application/json"}, timeout=5).text
  File "/usr/local/lib/python3.6/dist-packages/requests/api.py", line 117, in post
    return request('post', url, data=data, json=json, **kwargs)
  File "/usr/local/lib/python3.6/dist-packages/requests/api.py", line 61, in request
    return session.request(method=method, url=url, **kwargs)
  File "/usr/local/lib/python3.6/dist-packages/requests/sessions.py", line 542, in request
    resp = self.send(prep, **send_kwargs)
  File "/usr/local/lib/python3.6/dist-packages/requests/sessions.py", line 655, in send
    r = adapter.send(request, **kwargs)
  File "/usr/local/lib/python3.6/dist-packages/requests/adapters.py", line 516, in send
    raise ConnectionError(e, request=request)
requests.exceptions.ConnectionError: HTTPConnectionPool(host='oj-backend', port=8000): Max retries exceeded with url: /api/judge_server_heartbeat/ (Caused by NewConnectionError('<urllib3.connection.HTTPConnection object at 0x7f44c39687f0>: Failed to establish a new connection: [Errno 111] Connection refused',))

During handling of the above exception, another exception occurred:

Traceback (most recent call last):
  File "/code/service.py", line 42, in <module>
    service.heartbeat()
  File "/code/service.py", line 35, in heartbeat
    self._request(data)
  File "/code/service.py", line 22, in _request
    raise JudgeServiceError("Heartbeat request failed")
exception.JudgeServiceError
