[2023-03-21 14:23:54 +0000] [124] [INFO] Starting gunicorn 20.1.0
[2023-03-21 14:23:54 +0000] [124] [INFO] Listening at: http://127.0.0.1:8080 (124)
[2023-03-21 14:23:54 +0000] [124] [INFO] Using worker: gthread
[2023-03-21 14:23:54 +0000] [132] [INFO] Booting worker with pid: 132
[2023-03-21 14:23:54 +0000] [133] [INFO] Booting worker with pid: 133
[2023-03-21 14:23:54 +0000] [134] [INFO] Booting worker with pid: 134
[2023-03-21 14:23:54 +0000] [135] [INFO] Booting worker with pid: 135
[2023-03-21 14:35:01] - [ERROR] - [root:156]  - MISCONF Redis is configured to save RDB snapshots, but it is currently not able to persist on disk. Commands that may modify the data set are disabled, because this instance is configured to report errors during writes if RDB snapshotting fails (stop-writes-on-bgsave-error option). Please check the Redis logs for details about the RDB error.
Traceback (most recent call last):
  File "/usr/local/lib/python3.8/site-packages/django_redis/cache.py", line 31, in _decorator
    return method(self, *args, **kwargs)
  File "/usr/local/lib/python3.8/site-packages/django_redis/cache.py", line 88, in add
    return self.client.add(*args, **kwargs)
  File "/usr/local/lib/python3.8/site-packages/django_redis/client/default.py", line 238, in add
    return self.set(key, value, timeout, version=version, client=client, nx=True)
  File "/usr/local/lib/python3.8/site-packages/django_redis/client/default.py", line 185, in set
    raise ConnectionInterrupted(connection=client) from e
django_redis.exceptions.ConnectionInterrupted: Redis ResponseError: MISCONF Redis is configured to save RDB snapshots, but it is currently not able to persist on disk. Commands that may modify the data set are disabled, because this instance is configured to report errors during writes if RDB snapshotting fails (stop-writes-on-bgsave-error option). Please check the Redis logs for details about the RDB error.

During handling of the above exception, another exception occurred:

Traceback (most recent call last):
  File "/app/utils/api/api.py", line 149, in dispatch
    return super(APIView, self).dispatch(request, *args, **kwargs)
  File "/usr/local/lib/python3.8/site-packages/django/views/generic/base.py", line 98, in dispatch
    return handler(request, *args, **kwargs)
  File "/app/utils/api/api.py", line 181, in handle
    return view_method(*args, **kwargs)
  File "/app/account/views/oj.py", line 168, in post
    auth.login(request, user)
  File "/usr/local/lib/python3.8/site-packages/django/contrib/auth/__init__.py", line 111, in login
    request.session.cycle_key()
  File "/usr/local/lib/python3.8/site-packages/django/contrib/sessions/backends/base.py", line 344, in cycle_key
    self.create()
  File "/usr/local/lib/python3.8/site-packages/django/contrib/sessions/backends/cache.py", line 45, in create
    self.save(must_create=True)
  File "/usr/local/lib/python3.8/site-packages/django/contrib/sessions/backends/cache.py", line 63, in save
    result = func(self.cache_key,
  File "/usr/local/lib/python3.8/site-packages/django_redis/cache.py", line 38, in _decorator
    raise e.__cause__
  File "/usr/local/lib/python3.8/site-packages/django_redis/client/default.py", line 175, in set
    return bool(client.set(nkey, nvalue, nx=nx, px=timeout, xx=xx))
  File "/usr/local/lib/python3.8/site-packages/redis/client.py", line 1801, in set
    return self.execute_command('SET', *pieces)
  File "/usr/local/lib/python3.8/site-packages/redis/client.py", line 901, in execute_command
    return self.parse_response(conn, command_name, **options)
  File "/usr/local/lib/python3.8/site-packages/redis/client.py", line 915, in parse_response
    response = connection.read_response()
  File "/usr/local/lib/python3.8/site-packages/redis/connection.py", line 756, in read_response
    raise response
redis.exceptions.ResponseError: MISCONF Redis is configured to save RDB snapshots, but it is currently not able to persist on disk. Commands that may modify the data set are disabled, because this instance is configured to report errors during writes if RDB snapshotting fails (stop-writes-on-bgsave-error option). Please check the Redis logs for details about the RDB error.
[2023-03-21 14:35:03] - [ERROR] - [sentry.errors:682]  - Sentry responded with an API error: RateLimited(None)
b'Sentry responded with an API error: RateLimited(None)'
[2023-03-21 14:35:03] - [ERROR] - [sentry.errors.uncaught:712]  - ['MISCONF Redis is configured to save RDB snapshots, but it is currently not able to persist on disk. Commands that may modify the data set are disabled, because this instance is configured to report errors during writes if RDB snapshotting fails (stop-writes-on-bgsave-error option). Please check the Redis logs for details about the RDB error.', '  File "utils/api/api.py", line 149, in dispatch', '  File "django/views/generic/base.py", line 98, in dispatch', '  File "utils/api/api.py", line 181, in handle', '  File "account/views/oj.py", line 168, in post', '  File "django/contrib/auth/__init__.py", line 111, in login', '  File "django/contrib/sessions/backends/base.py", line 344, in cycle_key', '  File "django/contrib/sessions/backends/cache.py", line 45, in create', '  File "django/contrib/sessions/backends/cache.py", line 63, in save', '  File "django_redis/cache.py", line 38, in _decorator', '  File "django_redis/client/default.py", line 175, in set', '  File "redis/client.py", line 1801, in set', '  File "redis/client.py", line 901, in execute_command', '  File "redis/client.py", line 915, in parse_response', '  File "redis/connection.py", line 756, in read_response']
b'[\'MISCONF Redis is configured to save RDB snapshots, but it is currently not able to persist on disk. Commands that may modify the data set are disabled, because this instance is configured to report errors during writes if RDB snapshotting fails (stop-writes-on-bgsave-error option). Please check the Redis logs for details about the RDB error.\', \'  File "utils/api/api.py", line 149, in dispatch\', \'  File "django/views/generic/base.py", line 98, in dispatch\', \'  File "utils/api/api.py", line 181, in handle\', \'  File "account/views/oj.py", line 168, in post\', \'  File "django/contrib/auth/__init__.py", line 111, in login\', \'  File "django/contrib/sessions/backends/base.py", line 344, in cycle_key\', \'  File "django/contrib/sessions/backends/cache.py", line 45, in create\', \'  File "django/contrib/sessions/backends/cache.py", line 63, in save\', \'  File "django_redis/cache.py", line 38, in _decorator\', \'  File "django_redis/client/default.py", line 175, in set\', \'  File "redis/client.py", line 1801, in set\', \'  File "redis/client.py", line 901, in execute_command\', \'  File "redis/client.py", line 915, in parse_response\', \'  File "redis/connection.py", line 756, in read_response\']'
[2023-03-21 14:35:05] - [ERROR] - [root:156]  - MISCONF Redis is configured to save RDB snapshots, but it is currently not able to persist on disk. Commands that may modify the data set are disabled, because this instance is configured to report errors during writes if RDB snapshotting fails (stop-writes-on-bgsave-error option). Please check the Redis logs for details about the RDB error.
Traceback (most recent call last):
  File "/usr/local/lib/python3.8/site-packages/django_redis/cache.py", line 31, in _decorator
    return method(self, *args, **kwargs)
  File "/usr/local/lib/python3.8/site-packages/django_redis/cache.py", line 88, in add
    return self.client.add(*args, **kwargs)
  File "/usr/local/lib/python3.8/site-packages/django_redis/client/default.py", line 238, in add
    return self.set(key, value, timeout, version=version, client=client, nx=True)
  File "/usr/local/lib/python3.8/site-packages/django_redis/client/default.py", line 185, in set
    raise ConnectionInterrupted(connection=client) from e
django_redis.exceptions.ConnectionInterrupted: Redis ResponseError: MISCONF Redis is configured to save RDB snapshots, but it is currently not able to persist on disk. Commands that may modify the data set are disabled, because this instance is configured to report errors during writes if RDB snapshotting fails (stop-writes-on-bgsave-error option). Please check the Redis logs for details about the RDB error.

During handling of the above exception, another exception occurred:

Traceback (most recent call last):
  File "/app/utils/api/api.py", line 149, in dispatch
    return super(APIView, self).dispatch(request, *args, **kwargs)
  File "/usr/local/lib/python3.8/site-packages/django/views/generic/base.py", line 98, in dispatch
    return handler(request, *args, **kwargs)
  File "/app/utils/api/api.py", line 181, in handle
    return view_method(*args, **kwargs)
  File "/app/account/views/oj.py", line 168, in post
    auth.login(request, user)
  File "/usr/local/lib/python3.8/site-packages/django/contrib/auth/__init__.py", line 111, in login
    request.session.cycle_key()
  File "/usr/local/lib/python3.8/site-packages/django/contrib/sessions/backends/base.py", line 344, in cycle_key
    self.create()
  File "/usr/local/lib/python3.8/site-packages/django/contrib/sessions/backends/cache.py", line 45, in create
    self.save(must_create=True)
  File "/usr/local/lib/python3.8/site-packages/django/contrib/sessions/backends/cache.py", line 63, in save
    result = func(self.cache_key,
  File "/usr/local/lib/python3.8/site-packages/django_redis/cache.py", line 38, in _decorator
    raise e.__cause__
  File "/usr/local/lib/python3.8/site-packages/django_redis/client/default.py", line 175, in set
    return bool(client.set(nkey, nvalue, nx=nx, px=timeout, xx=xx))
  File "/usr/local/lib/python3.8/site-packages/redis/client.py", line 1801, in set
    return self.execute_command('SET', *pieces)
  File "/usr/local/lib/python3.8/site-packages/redis/client.py", line 901, in execute_command
    return self.parse_response(conn, command_name, **options)
  File "/usr/local/lib/python3.8/site-packages/redis/client.py", line 915, in parse_response
    response = connection.read_response()
  File "/usr/local/lib/python3.8/site-packages/redis/connection.py", line 756, in read_response
    raise response
redis.exceptions.ResponseError: MISCONF Redis is configured to save RDB snapshots, but it is currently not able to persist on disk. Commands that may modify the data set are disabled, because this instance is configured to report errors during writes if RDB snapshotting fails (stop-writes-on-bgsave-error option). Please check the Redis logs for details about the RDB error.
[2023-03-21 14:35:05] - [ERROR] - [sentry.errors.uncaught:712]  - ['MISCONF Redis is configured to save RDB snapshots, but it is currently not able to persist on disk. Commands that may modify the data set are disabled, because this instance is configured to report errors during writes if RDB snapshotting fails (stop-writes-on-bgsave-error option). Please check the Redis logs for details about the RDB error.', '  File "utils/api/api.py", line 149, in dispatch', '  File "django/views/generic/base.py", line 98, in dispatch', '  File "utils/api/api.py", line 181, in handle', '  File "account/views/oj.py", line 168, in post', '  File "django/contrib/auth/__init__.py", line 111, in login', '  File "django/contrib/sessions/backends/base.py", line 344, in cycle_key', '  File "django/contrib/sessions/backends/cache.py", line 45, in create', '  File "django/contrib/sessions/backends/cache.py", line 63, in save', '  File "django_redis/cache.py", line 38, in _decorator', '  File "django_redis/client/default.py", line 175, in set', '  File "redis/client.py", line 1801, in set', '  File "redis/client.py", line 901, in execute_command', '  File "redis/client.py", line 915, in parse_response', '  File "redis/connection.py", line 756, in read_response']
b'[\'MISCONF Redis is configured to save RDB snapshots, but it is currently not able to persist on disk. Commands that may modify the data set are disabled, because this instance is configured to report errors during writes if RDB snapshotting fails (stop-writes-on-bgsave-error option). Please check the Redis logs for details about the RDB error.\', \'  File "utils/api/api.py", line 149, in dispatch\', \'  File "django/views/generic/base.py", line 98, in dispatch\', \'  File "utils/api/api.py", line 181, in handle\', \'  File "account/views/oj.py", line 168, in post\', \'  File "django/contrib/auth/__init__.py", line 111, in login\', \'  File "django/contrib/sessions/backends/base.py", line 344, in cycle_key\', \'  File "django/contrib/sessions/backends/cache.py", line 45, in create\', \'  File "django/contrib/sessions/backends/cache.py", line 63, in save\', \'  File "django_redis/cache.py", line 38, in _decorator\', \'  File "django_redis/client/default.py", line 175, in set\', \'  File "redis/client.py", line 1801, in set\', \'  File "redis/client.py", line 901, in execute_command\', \'  File "redis/client.py", line 915, in parse_response\', \'  File "redis/connection.py", line 756, in read_response\']'
[2023-03-21 14:35:07] - [ERROR] - [root:156]  - MISCONF Redis is configured to save RDB snapshots, but it is currently not able to persist on disk. Commands that may modify the data set are disabled, because this instance is configured to report errors during writes if RDB snapshotting fails (stop-writes-on-bgsave-error option). Please check the Redis logs for details about the RDB error.
Traceback (most recent call last):
  File "/usr/local/lib/python3.8/site-packages/django_redis/cache.py", line 31, in _decorator
    return method(self, *args, **kwargs)
  File "/usr/local/lib/python3.8/site-packages/django_redis/cache.py", line 88, in add
    return self.client.add(*args, **kwargs)
  File "/usr/local/lib/python3.8/site-packages/django_redis/client/default.py", line 238, in add
    return self.set(key, value, timeout, version=version, client=client, nx=True)
  File "/usr/local/lib/python3.8/site-packages/django_redis/client/default.py", line 185, in set
    raise ConnectionInterrupted(connection=client) from e
django_redis.exceptions.ConnectionInterrupted: Redis ResponseError: MISCONF Redis is configured to save RDB snapshots, but it is currently not able to persist on disk. Commands that may modify the data set are disabled, because this instance is configured to report errors during writes if RDB snapshotting fails (stop-writes-on-bgsave-error option). Please check the Redis logs for details about the RDB error.

During handling of the above exception, another exception occurred:

Traceback (most recent call last):
  File "/app/utils/api/api.py", line 149, in dispatch
    return super(APIView, self).dispatch(request, *args, **kwargs)
  File "/usr/local/lib/python3.8/site-packages/django/views/generic/base.py", line 98, in dispatch
    return handler(request, *args, **kwargs)
  File "/app/utils/api/api.py", line 181, in handle
    return view_method(*args, **kwargs)
  File "/app/account/views/oj.py", line 168, in post
    auth.login(request, user)
  File "/usr/local/lib/python3.8/site-packages/django/contrib/auth/__init__.py", line 111, in login
    request.session.cycle_key()
  File "/usr/local/lib/python3.8/site-packages/django/contrib/sessions/backends/base.py", line 344, in cycle_key
    self.create()
  File "/usr/local/lib/python3.8/site-packages/django/contrib/sessions/backends/cache.py", line 45, in create
    self.save(must_create=True)
  File "/usr/local/lib/python3.8/site-packages/django/contrib/sessions/backends/cache.py", line 63, in save
    result = func(self.cache_key,
  File "/usr/local/lib/python3.8/site-packages/django_redis/cache.py", line 38, in _decorator
    raise e.__cause__
  File "/usr/local/lib/python3.8/site-packages/django_redis/client/default.py", line 175, in set
    return bool(client.set(nkey, nvalue, nx=nx, px=timeout, xx=xx))
  File "/usr/local/lib/python3.8/site-packages/redis/client.py", line 1801, in set
    return self.execute_command('SET', *pieces)
  File "/usr/local/lib/python3.8/site-packages/redis/client.py", line 901, in execute_command
    return self.parse_response(conn, command_name, **options)
  File "/usr/local/lib/python3.8/site-packages/redis/client.py", line 915, in parse_response
    response = connection.read_response()
  File "/usr/local/lib/python3.8/site-packages/redis/connection.py", line 756, in read_response
    raise response
redis.exceptions.ResponseError: MISCONF Redis is configured to save RDB snapshots, but it is currently not able to persist on disk. Commands that may modify the data set are disabled, because this instance is configured to report errors during writes if RDB snapshotting fails (stop-writes-on-bgsave-error option). Please check the Redis logs for details about the RDB error.
[2023-03-21 14:35:07] - [ERROR] - [sentry.errors.uncaught:712]  - ['MISCONF Redis is configured to save RDB snapshots, but it is currently not able to persist on disk. Commands that may modify the data set are disabled, because this instance is configured to report errors during writes if RDB snapshotting fails (stop-writes-on-bgsave-error option). Please check the Redis logs for details about the RDB error.', '  File "utils/api/api.py", line 149, in dispatch', '  File "django/views/generic/base.py", line 98, in dispatch', '  File "utils/api/api.py", line 181, in handle', '  File "account/views/oj.py", line 168, in post', '  File "django/contrib/auth/__init__.py", line 111, in login', '  File "django/contrib/sessions/backends/base.py", line 344, in cycle_key', '  File "django/contrib/sessions/backends/cache.py", line 45, in create', '  File "django/contrib/sessions/backends/cache.py", line 63, in save', '  File "django_redis/cache.py", line 38, in _decorator', '  File "django_redis/client/default.py", line 175, in set', '  File "redis/client.py", line 1801, in set', '  File "redis/client.py", line 901, in execute_command', '  File "redis/client.py", line 915, in parse_response', '  File "redis/connection.py", line 756, in read_response']
[2023-03-21 14:35:11] - [ERROR] - [root:156]  - MISCONF Redis is configured to save RDB snapshots, but it is currently not able to persist on disk. Commands that may modify the data set are disabled, because this instance is configured to report errors during writes if RDB snapshotting fails (stop-writes-on-bgsave-error option). Please check the Redis logs for details about the RDB error.
Traceback (most recent call last):
  File "/usr/local/lib/python3.8/site-packages/django_redis/cache.py", line 31, in _decorator
    return method(self, *args, **kwargs)
  File "/usr/local/lib/python3.8/site-packages/django_redis/cache.py", line 88, in add
    return self.client.add(*args, **kwargs)
  File "/usr/local/lib/python3.8/site-packages/django_redis/client/default.py", line 238, in add
    return self.set(key, value, timeout, version=version, client=client, nx=True)
  File "/usr/local/lib/python3.8/site-packages/django_redis/client/default.py", line 185, in set
    raise ConnectionInterrupted(connection=client) from e
django_redis.exceptions.ConnectionInterrupted: Redis ResponseError: MISCONF Redis is configured to save RDB snapshots, but it is currently not able to persist on disk. Commands that may modify the data set are disabled, because this instance is configured to report errors during writes if RDB snapshotting fails (stop-writes-on-bgsave-error option). Please check the Redis logs for details about the RDB error.

During handling of the above exception, another exception occurred:

Traceback (most recent call last):
  File "/app/utils/api/api.py", line 149, in dispatch
    return super(APIView, self).dispatch(request, *args, **kwargs)
  File "/usr/local/lib/python3.8/site-packages/django/views/generic/base.py", line 98, in dispatch
    return handler(request, *args, **kwargs)
  File "/app/utils/api/api.py", line 181, in handle
    return view_method(*args, **kwargs)
  File "/app/account/views/oj.py", line 168, in post
    auth.login(request, user)
  File "/usr/local/lib/python3.8/site-packages/django/contrib/auth/__init__.py", line 111, in login
    request.session.cycle_key()
  File "/usr/local/lib/python3.8/site-packages/django/contrib/sessions/backends/base.py", line 344, in cycle_key
    self.create()
  File "/usr/local/lib/python3.8/site-packages/django/contrib/sessions/backends/cache.py", line 45, in create
    self.save(must_create=True)
  File "/usr/local/lib/python3.8/site-packages/django/contrib/sessions/backends/cache.py", line 63, in save
    result = func(self.cache_key,
  File "/usr/local/lib/python3.8/site-packages/django_redis/cache.py", line 38, in _decorator
    raise e.__cause__
  File "/usr/local/lib/python3.8/site-packages/django_redis/client/default.py", line 175, in set
    return bool(client.set(nkey, nvalue, nx=nx, px=timeout, xx=xx))
  File "/usr/local/lib/python3.8/site-packages/redis/client.py", line 1801, in set
    return self.execute_command('SET', *pieces)
  File "/usr/local/lib/python3.8/site-packages/redis/client.py", line 901, in execute_command
    return self.parse_response(conn, command_name, **options)
  File "/usr/local/lib/python3.8/site-packages/redis/client.py", line 915, in parse_response
    response = connection.read_response()
  File "/usr/local/lib/python3.8/site-packages/redis/connection.py", line 756, in read_response
    raise response
redis.exceptions.ResponseError: MISCONF Redis is configured to save RDB snapshots, but it is currently not able to persist on disk. Commands that may modify the data set are disabled, because this instance is configured to report errors during writes if RDB snapshotting fails (stop-writes-on-bgsave-error option). Please check the Redis logs for details about the RDB error.
[2023-03-21 14:35:12] - [ERROR] - [sentry.errors:682]  - Sentry responded with an API error: RateLimited(None)
b'Sentry responded with an API error: RateLimited(None)'
[2023-03-21 14:35:12] - [ERROR] - [sentry.errors.uncaught:712]  - ['MISCONF Redis is configured to save RDB snapshots, but it is currently not able to persist on disk. Commands that may modify the data set are disabled, because this instance is configured to report errors during writes if RDB snapshotting fails (stop-writes-on-bgsave-error option). Please check the Redis logs for details about the RDB error.', '  File "utils/api/api.py", line 149, in dispatch', '  File "django/views/generic/base.py", line 98, in dispatch', '  File "utils/api/api.py", line 181, in handle', '  File "account/views/oj.py", line 168, in post', '  File "django/contrib/auth/__init__.py", line 111, in login', '  File "django/contrib/sessions/backends/base.py", line 344, in cycle_key', '  File "django/contrib/sessions/backends/cache.py", line 45, in create', '  File "django/contrib/sessions/backends/cache.py", line 63, in save', '  File "django_redis/cache.py", line 38, in _decorator', '  File "django_redis/client/default.py", line 175, in set', '  File "redis/client.py", line 1801, in set', '  File "redis/client.py", line 901, in execute_command', '  File "redis/client.py", line 915, in parse_response', '  File "redis/connection.py", line 756, in read_response']
b'[\'MISCONF Redis is configured to save RDB snapshots, but it is currently not able to persist on disk. Commands that may modify the data set are disabled, because this instance is configured to report errors during writes if RDB snapshotting fails (stop-writes-on-bgsave-error option). Please check the Redis logs for details about the RDB error.\', \'  File "utils/api/api.py", line 149, in dispatch\', \'  File "django/views/generic/base.py", line 98, in dispatch\', \'  File "utils/api/api.py", line 181, in handle\', \'  File "account/views/oj.py", line 168, in post\', \'  File "django/contrib/auth/__init__.py", line 111, in login\', \'  File "django/contrib/sessions/backends/base.py", line 344, in cycle_key\', \'  File "django/contrib/sessions/backends/cache.py", line 45, in create\', \'  File "django/contrib/sessions/backends/cache.py", line 63, in save\', \'  File "django_redis/cache.py", line 38, in _decorator\', \'  File "django_redis/client/default.py", line 175, in set\', \'  File "redis/client.py", line 1801, in set\', \'  File "redis/client.py", line 901, in execute_command\', \'  File "redis/client.py", line 915, in parse_response\', \'  File "redis/connection.py", line 756, in read_response\']'
[2023-03-21 14:35:12] - [ERROR] - [root:156]  - MISCONF Redis is configured to save RDB snapshots, but it is currently not able to persist on disk. Commands that may modify the data set are disabled, because this instance is configured to report errors during writes if RDB snapshotting fails (stop-writes-on-bgsave-error option). Please check the Redis logs for details about the RDB error.
Traceback (most recent call last):
  File "/usr/local/lib/python3.8/site-packages/django_redis/cache.py", line 31, in _decorator
    return method(self, *args, **kwargs)
  File "/usr/local/lib/python3.8/site-packages/django_redis/cache.py", line 88, in add
    return self.client.add(*args, **kwargs)
  File "/usr/local/lib/python3.8/site-packages/django_redis/client/default.py", line 238, in add
    return self.set(key, value, timeout, version=version, client=client, nx=True)
  File "/usr/local/lib/python3.8/site-packages/django_redis/client/default.py", line 185, in set
    raise ConnectionInterrupted(connection=client) from e
django_redis.exceptions.ConnectionInterrupted: Redis ResponseError: MISCONF Redis is configured to save RDB snapshots, but it is currently not able to persist on disk. Commands that may modify the data set are disabled, because this instance is configured to report errors during writes if RDB snapshotting fails (stop-writes-on-bgsave-error option). Please check the Redis logs for details about the RDB error.

During handling of the above exception, another exception occurred:

Traceback (most recent call last):
  File "/app/utils/api/api.py", line 149, in dispatch
    return super(APIView, self).dispatch(request, *args, **kwargs)
  File "/usr/local/lib/python3.8/site-packages/django/views/generic/base.py", line 98, in dispatch
    return handler(request, *args, **kwargs)
  File "/app/utils/api/api.py", line 181, in handle
    return view_method(*args, **kwargs)
  File "/app/account/views/oj.py", line 168, in post
    auth.login(request, user)
  File "/usr/local/lib/python3.8/site-packages/django/contrib/auth/__init__.py", line 111, in login
    request.session.cycle_key()
  File "/usr/local/lib/python3.8/site-packages/django/contrib/sessions/backends/base.py", line 344, in cycle_key
    self.create()
  File "/usr/local/lib/python3.8/site-packages/django/contrib/sessions/backends/cache.py", line 45, in create
    self.save(must_create=True)
  File "/usr/local/lib/python3.8/site-packages/django/contrib/sessions/backends/cache.py", line 63, in save
    result = func(self.cache_key,
  File "/usr/local/lib/python3.8/site-packages/django_redis/cache.py", line 38, in _decorator
    raise e.__cause__
  File "/usr/local/lib/python3.8/site-packages/django_redis/client/default.py", line 175, in set
    return bool(client.set(nkey, nvalue, nx=nx, px=timeout, xx=xx))
  File "/usr/local/lib/python3.8/site-packages/redis/client.py", line 1801, in set
    return self.execute_command('SET', *pieces)
  File "/usr/local/lib/python3.8/site-packages/redis/client.py", line 901, in execute_command
    return self.parse_response(conn, command_name, **options)
  File "/usr/local/lib/python3.8/site-packages/redis/client.py", line 915, in parse_response
    response = connection.read_response()
  File "/usr/local/lib/python3.8/site-packages/redis/connection.py", line 756, in read_response
    raise response
redis.exceptions.ResponseError: MISCONF Redis is configured to save RDB snapshots, but it is currently not able to persist on disk. Commands that may modify the data set are disabled, because this instance is configured to report errors during writes if RDB snapshotting fails (stop-writes-on-bgsave-error option). Please check the Redis logs for details about the RDB error.
[2023-03-21 14:35:13] - [ERROR] - [sentry.errors.uncaught:712]  - ['MISCONF Redis is configured to save RDB snapshots, but it is currently not able to persist on disk. Commands that may modify the data set are disabled, because this instance is configured to report errors during writes if RDB snapshotting fails (stop-writes-on-bgsave-error option). Please check the Redis logs for details about the RDB error.', '  File "utils/api/api.py", line 149, in dispatch', '  File "django/views/generic/base.py", line 98, in dispatch', '  File "utils/api/api.py", line 181, in handle', '  File "account/views/oj.py", line 168, in post', '  File "django/contrib/auth/__init__.py", line 111, in login', '  File "django/contrib/sessions/backends/base.py", line 344, in cycle_key', '  File "django/contrib/sessions/backends/cache.py", line 45, in create', '  File "django/contrib/sessions/backends/cache.py", line 63, in save', '  File "django_redis/cache.py", line 38, in _decorator', '  File "django_redis/client/default.py", line 175, in set', '  File "redis/client.py", line 1801, in set', '  File "redis/client.py", line 901, in execute_command', '  File "redis/client.py", line 915, in parse_response', '  File "redis/connection.py", line 756, in read_response']
b'[\'MISCONF Redis is configured to save RDB snapshots, but it is currently not able to persist on disk. Commands that may modify the data set are disabled, because this instance is configured to report errors during writes if RDB snapshotting fails (stop-writes-on-bgsave-error option). Please check the Redis logs for details about the RDB error.\', \'  File "utils/api/api.py", line 149, in dispatch\', \'  File "django/views/generic/base.py", line 98, in dispatch\', \'  File "utils/api/api.py", line 181, in handle\', \'  File "account/views/oj.py", line 168, in post\', \'  File "django/contrib/auth/__init__.py", line 111, in login\', \'  File "django/contrib/sessions/backends/base.py", line 344, in cycle_key\', \'  File "django/contrib/sessions/backends/cache.py", line 45, in create\', \'  File "django/contrib/sessions/backends/cache.py", line 63, in save\', \'  File "django_redis/cache.py", line 38, in _decorator\', \'  File "django_redis/client/default.py", line 175, in set\', \'  File "redis/client.py", line 1801, in set\', \'  File "redis/client.py", line 901, in execute_command\', \'  File "redis/client.py", line 915, in parse_response\', \'  File "redis/connection.py", line 756, in read_response\']'
[2023-03-21 14:35:41] - [ERROR] - [root:156]  - MISCONF Redis is configured to save RDB snapshots, but it is currently not able to persist on disk. Commands that may modify the data set are disabled, because this instance is configured to report errors during writes if RDB snapshotting fails (stop-writes-on-bgsave-error option). Please check the Redis logs for details about the RDB error.
Traceback (most recent call last):
  File "/usr/local/lib/python3.8/site-packages/django_redis/cache.py", line 31, in _decorator
    return method(self, *args, **kwargs)
  File "/usr/local/lib/python3.8/site-packages/django_redis/cache.py", line 88, in add
    return self.client.add(*args, **kwargs)
  File "/usr/local/lib/python3.8/site-packages/django_redis/client/default.py", line 238, in add
    return self.set(key, value, timeout, version=version, client=client, nx=True)
  File "/usr/local/lib/python3.8/site-packages/django_redis/client/default.py", line 185, in set
    raise ConnectionInterrupted(connection=client) from e
django_redis.exceptions.ConnectionInterrupted: Redis ResponseError: MISCONF Redis is configured to save RDB snapshots, but it is currently not able to persist on disk. Commands that may modify the data set are disabled, because this instance is configured to report errors during writes if RDB snapshotting fails (stop-writes-on-bgsave-error option). Please check the Redis logs for details about the RDB error.

During handling of the above exception, another exception occurred:

Traceback (most recent call last):
  File "/app/utils/api/api.py", line 149, in dispatch
    return super(APIView, self).dispatch(request, *args, **kwargs)
  File "/usr/local/lib/python3.8/site-packages/django/views/generic/base.py", line 98, in dispatch
    return handler(request, *args, **kwargs)
  File "/app/utils/api/api.py", line 181, in handle
    return view_method(*args, **kwargs)
  File "/app/account/views/oj.py", line 168, in post
    auth.login(request, user)
  File "/usr/local/lib/python3.8/site-packages/django/contrib/auth/__init__.py", line 111, in login
    request.session.cycle_key()
  File "/usr/local/lib/python3.8/site-packages/django/contrib/sessions/backends/base.py", line 344, in cycle_key
    self.create()
  File "/usr/local/lib/python3.8/site-packages/django/contrib/sessions/backends/cache.py", line 45, in create
    self.save(must_create=True)
  File "/usr/local/lib/python3.8/site-packages/django/contrib/sessions/backends/cache.py", line 63, in save
    result = func(self.cache_key,
  File "/usr/local/lib/python3.8/site-packages/django_redis/cache.py", line 38, in _decorator
    raise e.__cause__
  File "/usr/local/lib/python3.8/site-packages/django_redis/client/default.py", line 175, in set
    return bool(client.set(nkey, nvalue, nx=nx, px=timeout, xx=xx))
  File "/usr/local/lib/python3.8/site-packages/redis/client.py", line 1801, in set
    return self.execute_command('SET', *pieces)
  File "/usr/local/lib/python3.8/site-packages/redis/client.py", line 901, in execute_command
    return self.parse_response(conn, command_name, **options)
  File "/usr/local/lib/python3.8/site-packages/redis/client.py", line 915, in parse_response
    response = connection.read_response()
  File "/usr/local/lib/python3.8/site-packages/redis/connection.py", line 756, in read_response
    raise response
redis.exceptions.ResponseError: MISCONF Redis is configured to save RDB snapshots, but it is currently not able to persist on disk. Commands that may modify the data set are disabled, because this instance is configured to report errors during writes if RDB snapshotting fails (stop-writes-on-bgsave-error option). Please check the Redis logs for details about the RDB error.
[2023-03-21 14:35:41] - [ERROR] - [sentry.errors.uncaught:712]  - ['MISCONF Redis is configured to save RDB snapshots, but it is currently not able to persist on disk. Commands that may modify the data set are disabled, because this instance is configured to report errors during writes if RDB snapshotting fails (stop-writes-on-bgsave-error option). Please check the Redis logs for details about the RDB error.', '  File "utils/api/api.py", line 149, in dispatch', '  File "django/views/generic/base.py", line 98, in dispatch', '  File "utils/api/api.py", line 181, in handle', '  File "account/views/oj.py", line 168, in post', '  File "django/contrib/auth/__init__.py", line 111, in login', '  File "django/contrib/sessions/backends/base.py", line 344, in cycle_key', '  File "django/contrib/sessions/backends/cache.py", line 45, in create', '  File "django/contrib/sessions/backends/cache.py", line 63, in save', '  File "django_redis/cache.py", line 38, in _decorator', '  File "django_redis/client/default.py", line 175, in set', '  File "redis/client.py", line 1801, in set', '  File "redis/client.py", line 901, in execute_command', '  File "redis/client.py", line 915, in parse_response', '  File "redis/connection.py", line 756, in read_response']
[2023-03-21 14:36:09 +0000] [124] [INFO] Handling signal: term
[2023-03-21 14:36:09 +0000] [135] [INFO] Worker exiting (pid: 135)
b'[\'MISCONF Redis is configured to save RDB snapshots, but it is currently not able to persist on disk. Commands that may modify the data set are disabled, because this instance is configured to report errors during writes if RDB snapshotting fails (stop-writes-on-bgsave-error option). Please check the Redis logs for details about the RDB error.\', \'  File "utils/api/api.py", line 149, in dispatch\', \'  File "django/views/generic/base.py", line 98, in dispatch\', \'  File "utils/api/api.py", line 181, in handle\', \'  File "account/views/oj.py", line 168, in post\', \'  File "django/contrib/auth/__init__.py", line 111, in login\', \'  File "django/contrib/sessions/backends/base.py", line 344, in cycle_key\', \'  File "django/contrib/sessions/backends/cache.py", line 45, in create\', \'  File "django/contrib/sessions/backends/cache.py", line 63, in save\', \'  File "django_redis/cache.py", line 38, in _decorator\', \'  File "django_redis/client/default.py", line 175, in set\', \'  File "redis/client.py", line 1801, in set\', \'  File "redis/client.py", line 901, in execute_command\', \'  File "redis/client.py", line 915, in parse_response\', \'  File "redis/connection.py", line 756, in read_response\']'
[2023-03-21 14:36:09 +0000] [134] [INFO] Worker exiting (pid: 134)
[2023-03-21 14:36:10 +0000] [132] [INFO] Worker exiting (pid: 132)
b'[\'MISCONF Redis is configured to save RDB snapshots, but it is currently not able to persist on disk. Commands that may modify the data set are disabled, because this instance is configured to report errors during writes if RDB snapshotting fails (stop-writes-on-bgsave-error option). Please check the Redis logs for details about the RDB error.\', \'  File "utils/api/api.py", line 149, in dispatch\', \'  File "django/views/generic/base.py", line 98, in dispatch\', \'  File "utils/api/api.py", line 181, in handle\', \'  File "account/views/oj.py", line 168, in post\', \'  File "django/contrib/auth/__init__.py", line 111, in login\', \'  File "django/contrib/sessions/backends/base.py", line 344, in cycle_key\', \'  File "django/contrib/sessions/backends/cache.py", line 45, in create\', \'  File "django/contrib/sessions/backends/cache.py", line 63, in save\', \'  File "django_redis/cache.py", line 38, in _decorator\', \'  File "django_redis/client/default.py", line 175, in set\', \'  File "redis/client.py", line 1801, in set\', \'  File "redis/client.py", line 901, in execute_command\', \'  File "redis/client.py", line 915, in parse_response\', \'  File "redis/connection.py", line 756, in read_response\']'
[2023-03-21 14:36:10 +0000] [133] [INFO] Worker exiting (pid: 133)
[2023-03-21 14:36:10 +0000] [124] [INFO] Shutting down: Master
[2023-03-21 14:45:58 +0000] [110] [INFO] Starting gunicorn 20.1.0
[2023-03-21 14:45:58 +0000] [110] [INFO] Listening at: http://127.0.0.1:8080 (110)
[2023-03-21 14:45:58 +0000] [110] [INFO] Using worker: gthread
[2023-03-21 14:45:58 +0000] [118] [INFO] Booting worker with pid: 118
[2023-03-21 14:45:58 +0000] [119] [INFO] Booting worker with pid: 119
[2023-03-21 14:45:58 +0000] [120] [INFO] Booting worker with pid: 120
[2023-03-21 14:45:59 +0000] [121] [INFO] Booting worker with pid: 121
[2023-03-21 14:48:56] - [DEBUG] - [dramatiq.broker.RedisBroker:184]  - Enqueueing message 'd496b038-122c-4eab-90e4-5e46ccb5fb72' on queue 'default'.
[2023-03-21 14:49:11] - [DEBUG] - [dramatiq.broker.RedisBroker:184]  - Enqueueing message '86ac292b-31f3-4758-8848-b7c6e24489e4' on queue 'default'.
[2023-03-21 14:50:12 +0000] [110] [INFO] Handling signal: term
[2023-03-21 14:50:12 +0000] [120] [INFO] Worker exiting (pid: 120)
[2023-03-21 14:50:12 +0000] [119] [INFO] Worker exiting (pid: 119)
[2023-03-21 14:50:13 +0000] [121] [INFO] Worker exiting (pid: 121)
[2023-03-21 14:50:13 +0000] [118] [INFO] Worker exiting (pid: 118)
[2023-03-21 14:50:13 +0000] [110] [INFO] Shutting down: Master
[2023-03-21 14:50:21 +0000] [115] [INFO] Starting gunicorn 20.1.0
[2023-03-21 14:50:21 +0000] [115] [INFO] Listening at: http://127.0.0.1:8080 (115)
[2023-03-21 14:50:21 +0000] [115] [INFO] Using worker: gthread
[2023-03-21 14:50:21 +0000] [123] [INFO] Booting worker with pid: 123
[2023-03-21 14:50:21 +0000] [124] [INFO] Booting worker with pid: 124
[2023-03-21 14:50:21 +0000] [125] [INFO] Booting worker with pid: 125
[2023-03-21 14:50:21 +0000] [126] [INFO] Booting worker with pid: 126
[2023-03-21 14:50:26] - [DEBUG] - [dramatiq.broker.RedisBroker:184]  - Enqueueing message 'b7ac7765-64b3-4e15-8b00-6cb87e099317' on queue 'default'.
[2023-03-21 14:50:54] - [DEBUG] - [dramatiq.broker.RedisBroker:184]  - Enqueueing message '35f4d80a-3a48-4c22-82c0-2f4cedef2206' on queue 'default'.
[2023-03-21 15:34:09 +0000] [115] [INFO] Handling signal: term
[2023-03-21 15:34:09 +0000] [123] [INFO] Worker exiting (pid: 123)
[2023-03-21 15:34:09 +0000] [126] [INFO] Worker exiting (pid: 126)
[2023-03-21 15:34:09 +0000] [125] [INFO] Worker exiting (pid: 125)
[2023-03-21 15:34:09 +0000] [124] [INFO] Worker exiting (pid: 124)
[2023-03-21 15:34:10 +0000] [115] [INFO] Shutting down: Master
